<mujoco model="g1_inspire">
  <compiler angle="radian" meshdir="meshes_g1_inspire"/>
    <default>
        <default class="torso_motor">
            <joint damping="0.05" armature="0.01" frictionloss="0.2"/>
        </default>
        <default class="leg_motor">
            <joint damping="0.05" armature="0.01" frictionloss="0.2"/>
        </default>
        <default class="ankle_motor">
            <joint damping="0.05" armature="0.01" frictionloss="0.2"/>
        </default>
        <default class="arm_motor">
            <joint damping="0.05" armature="0.01" frictionloss="0.2"/>
        </default>
        <default class="wrist_motor">
            <joint damping="0.05" armature="0.01" frictionloss="0.1"/>
        </default>

    </default>

  <asset>
    <material name="dark" rgba="0.2 0.2 0.2 1" />
    <material name="white" rgba="0.7 0.7 0.7 1" />
    <material name="07" rgba="0.792156862745098 0.819607843137255 0.933333333333333 1" />
    <material name="04" rgba="0.411764705882353 0.411764705882353 0.411764705882353 1" />
    <material name="1" rgba="1 1 1 1" />
    <material name="collision_material" rgba="1.0 0.28 0.1 0.9" />
    <mesh name="pelvis" file="pelvis.STL" />
    <mesh name="pelvis_contour_link" file="pelvis_contour_link.STL" />
    <mesh name="left_hip_pitch_link" file="left_hip_pitch_link.STL" />
    <mesh name="left_hip_roll_link" file="left_hip_roll_link.STL" />
    <mesh name="left_hip_yaw_link" file="left_hip_yaw_link.STL" />
    <mesh name="left_knee_link" file="left_knee_link.STL" />
    <mesh name="left_ankle_pitch_link" file="left_ankle_pitch_link.STL" />
    <mesh name="left_ankle_roll_link" file="left_ankle_roll_link.STL" />
    <mesh name="right_hip_pitch_link" file="right_hip_pitch_link.STL" />
    <mesh name="right_hip_roll_link" file="right_hip_roll_link.STL" />
    <mesh name="right_hip_yaw_link" file="right_hip_yaw_link.STL" />
    <mesh name="right_knee_link" file="right_knee_link.STL" />
    <mesh name="right_ankle_pitch_link" file="right_ankle_pitch_link.STL" />
    <mesh name="right_ankle_roll_link" file="right_ankle_roll_link.STL" />
    <mesh name="waist_yaw_link_rev_1_0" file="waist_yaw_link_rev_1_0.STL" />
    <mesh name="waist_roll_link_rev_1_0" file="waist_roll_link_rev_1_0.STL" />
    <mesh name="torso_link_rev_1_0" file="torso_link_rev_1_0.STL" />
    <mesh name="logo_link" file="logo_link.STL" />
    <mesh name="head_link" file="head_link.STL" />
    <mesh name="left_shoulder_pitch_link" file="left_shoulder_pitch_link.STL" />
    <mesh name="left_shoulder_roll_link" file="left_shoulder_roll_link.STL" />
    <mesh name="left_shoulder_yaw_link" file="left_shoulder_yaw_link.STL" />
    <mesh name="left_elbow_link" file="left_elbow_link.STL" />
    <mesh name="left_wrist_roll_link" file="left_wrist_roll_link.STL" />
    <mesh name="left_wrist_pitch_link" file="left_wrist_pitch_link.STL" />
    <mesh name="left_wrist_yaw_link" file="left_wrist_yaw_link.STL" />
    <mesh name="left_base_link" file="left_base_link.STL" />
    <mesh name="left_palm_force_sensor" file="left_palm_force_sensor.STL" />
    <mesh name="left_thumb_1" file="left_thumb_1.STL" />
    <mesh name="left_thumb_2" file="left_thumb_2.STL" />
    <mesh name="left_thumb_force_sensor_1" file="left_thumb_force_sensor_1.STL" />
    <mesh name="left_thumb_3" file="left_thumb_3.STL" />
    <mesh name="left_thumb_force_sensor_2" file="left_thumb_force_sensor_2.STL" />
    <mesh name="left_thumb_4" file="left_thumb_4.STL" />
    <mesh name="left_thumb_force_sensor_3" file="left_thumb_force_sensor_3.STL" />
    <mesh name="left_thumb_force_sensor_4" file="left_thumb_force_sensor_4.STL" />
    <mesh name="left_index_1" file="left_index_1.STL" />
    <mesh name="left_index_force_sensor_1" file="left_index_force_sensor_1.STL" />
    <mesh name="left_index_2" file="left_index_2.STL" />
    <mesh name="left_index_force_sensor_2" file="left_index_force_sensor_2.STL" />
    <mesh name="left_index_force_sensor_3" file="left_index_force_sensor_3.STL" />
    <mesh name="left_middle_1" file="left_middle_1.STL" />
    <mesh name="left_middle_force_sensor_1" file="left_middle_force_sensor_1.STL" />
    <mesh name="left_middle_2" file="left_middle_2.STL" />
    <mesh name="left_middle_force_sensor_2" file="left_middle_force_sensor_2.STL" />
    <mesh name="left_middle_force_sensor_3" file="left_middle_force_sensor_3.STL" />
    <mesh name="left_ring_1" file="left_ring_1.STL" />
    <mesh name="left_ring_force_sensor_1" file="left_ring_force_sensor_1.STL" />
    <mesh name="left_ring_2" file="left_ring_2.STL" />
    <mesh name="left_ring_force_sensor_2" file="left_ring_force_sensor_2.STL" />
    <mesh name="left_ring_force_sensor_3" file="left_ring_force_sensor_3.STL" />
    <mesh name="left_little_1" file="left_little_1.STL" />
    <mesh name="left_little_force_sensor_1" file="left_little_force_sensor_1.STL" />
    <mesh name="left_little_2" file="left_little_2.STL" />
    <mesh name="left_little_force_sensor_2" file="left_little_force_sensor_2.STL" />
    <mesh name="left_little_force_sensor_3" file="left_little_force_sensor_3.STL" />
    <mesh name="right_shoulder_pitch_link" file="right_shoulder_pitch_link.STL" />
    <mesh name="right_shoulder_roll_link" file="right_shoulder_roll_link.STL" />
    <mesh name="right_shoulder_yaw_link" file="right_shoulder_yaw_link.STL" />
    <mesh name="right_elbow_link" file="right_elbow_link.STL" />
    <mesh name="right_wrist_roll_link" file="right_wrist_roll_link.STL" />
    <mesh name="right_wrist_pitch_link" file="right_wrist_pitch_link.STL" />
    <mesh name="right_wrist_yaw_link" file="right_wrist_yaw_link.STL" />
    <mesh name="right_base_link" file="right_base_link.STL" />
    <mesh name="right_palm_force_sensor" file="right_palm_force_sensor.STL" />
    <mesh name="right_thumb_1" file="right_thumb_1.STL" />
    <mesh name="right_thumb_2" file="right_thumb_2.STL" />
    <mesh name="right_thumb_3" file="right_thumb_3.STL" />
    <mesh name="right_thumb_force_sensor_2" file="right_thumb_force_sensor_2.STL" />
    <mesh name="right_thumb_4" file="right_thumb_4.STL" />
    <mesh name="right_thumb_force_sensor_3" file="right_thumb_force_sensor_3.STL" />
    <mesh name="right_thumb_force_sensor_4" file="right_thumb_force_sensor_4.STL" />
    <mesh name="right_thumb_force_sensor_1" file="right_thumb_force_sensor_1.STL" />
    <mesh name="right_index_1" file="right_index_1.STL" />
    <mesh name="right_index_2" file="right_index_2.STL" />
    <mesh name="right_index_force_sensor_2" file="right_index_force_sensor_2.STL" />
    <mesh name="right_index_force_sensor_3" file="right_index_force_sensor_3.STL" />
    <mesh name="right_index_force_sensor_1" file="right_index_force_sensor_1.STL" />
    <mesh name="right_middle_1" file="right_middle_1.STL" />
    <mesh name="right_middle_2" file="right_middle_2.STL" />
    <mesh name="right_middle_force_sensor_2" file="right_middle_force_sensor_2.STL" />
    <mesh name="right_middle_force_sensor_3" file="right_middle_force_sensor_3.STL" />
    <mesh name="right_middle_force_sensor_1" file="right_middle_force_sensor_1.STL" />
    <mesh name="right_ring_1" file="right_ring_1.STL" />
    <mesh name="right_ring_2" file="right_ring_2.STL" />
    <mesh name="right_ring_force_sensor_2" file="right_ring_force_sensor_2.STL" />
    <mesh name="right_ring_force_sensor_3" file="right_ring_force_sensor_3.STL" />
    <mesh name="right_ring_force_sensor_1" file="right_ring_force_sensor_1.STL" />
    <mesh name="right_little_1" file="right_little_1.STL" />
    <mesh name="right_little_2" file="right_little_2.STL" />
    <mesh name="right_little_force_sensor_2" file="right_little_force_sensor_2.STL" />
    <mesh name="right_little_force_sensor_3" file="right_little_force_sensor_3.STL" />
    <mesh name="right_little_force_sensor_1" file="right_little_force_sensor_1.STL" />
  </asset>

  <worldbody>
      <body name="pelvis" pos="0 0 0.793">
      <site name="imu" size="0.01" pos="0.0 0.0 0.0"/>
      <inertial pos="0 0 -0.07605" quat="1 0 -0.000399148 0" mass="3.813" diaginertia="0.010549 0.0093089 0.0079184"/>
      <joint name="floating_base_joint" type="free" limited="false" actuatorfrclimited="false"/>
      <geom type="mesh" contype="0" conaffinity="0" group="1" density="0" rgba="0.2 0.2 0.2 1" mesh="pelvis"/>
      <geom type="mesh" contype="0" conaffinity="0" group="1" density="0" rgba="0.7 0.7 0.7 1" mesh="pelvis_contour_link"/>
      <geom type="mesh" rgba="0.7 0.7 0.7 1" mesh="pelvis_contour_link"/>
      
      <body name="left_hip_pitch_link" pos="0 0.064452 -0.1027" quat="1.0 0.0 0.0 0.0">
        <joint name="left_hip_pitch_joint" type="hinge" ref="0.0"  range="-2.5307 2.8798" axis="0 1 0" actuatorfrcrange="-88 88" class="leg_motor"/>
        <inertial pos="0.002741 0.047791 -0.02606" quat="1.0 0.0 0.0 0.0" mass="1.35" diaginertia="0.001811 0.0014193 0.0012812" />
        <geom name="left_hip_pitch_link_collision" pos="0 0 0" quat="1.0 0.0 0.0 0.0" type="mesh" mesh="left_hip_pitch_link"  />
        <geom name="left_hip_pitch_link_visual" pos="0 0 0" quat="1.0 0.0 0.0 0.0" material="dark" type="mesh" mesh="left_hip_pitch_link" />
        <body name="left_hip_roll_link" pos="0 0.052 -0.030465" quat="0.9961786849744957 0.0 -0.08733858026373247 0.0">
          <joint name="left_hip_roll_joint" type="hinge" ref="0.0"  range="-0.5236 2.9671" axis="1 0 0" actuatorfrcrange="-88 88" class="leg_motor"/>
          <inertial pos="0.029812 -0.001045 -0.087934" quat="1.0 0.0 0.0 0.0" mass="1.52" diaginertia="0.0023773 0.0024123 0.0016595" />
          <geom name="left_hip_roll_link_collision" pos="0 0 0" quat="1.0 0.0 0.0 0.0" type="mesh" mesh="left_hip_roll_link"  />
          <geom name="left_hip_roll_link_visual" pos="0 0 0" quat="1.0 0.0 0.0 0.0" material="white" type="mesh" mesh="left_hip_roll_link" />
          <body name="left_hip_yaw_link" pos="0.025001 0 -0.12412" quat="1.0 0.0 0.0 0.0">
            <joint name="left_hip_yaw_joint" type="hinge" ref="0.0"  range="-2.7576 2.7576" axis="0 0 1" actuatorfrcrange="-88 88" class="leg_motor"/>
            <inertial pos="-0.057709 -0.010981 -0.15078" quat="1.0 0.0 0.0 0.0" mass="1.702" diaginertia="0.0057774 0.0076124 0.003149" />
            <geom name="left_hip_yaw_link_collision" pos="0 0 0" quat="1.0 0.0 0.0 0.0" type="mesh" mesh="left_hip_yaw_link"  />
            <geom name="left_hip_yaw_link_visual" pos="0 0 0" quat="1.0 0.0 0.0 0.0" material="white" type="mesh" mesh="left_hip_yaw_link" />
            <body name="left_knee_link" pos="-0.078273 0.0021489 -0.17734" quat="0.9961786849744957 0.0 0.08733858026373247 0.0">
              <joint name="left_knee_joint" type="hinge" ref="0.0"  range="-0.087267 2.8798" axis="0 1 0" actuatorfrcrange="-139 139" class="leg_motor"/>
              <inertial pos="0.005457 0.003964 -0.12074" quat="1.0 0.0 0.0 0.0" mass="1.932" diaginertia="0.011329 0.011277 0.0015168" />
              <geom name="left_knee_link_collision" pos="0 0 0" quat="1.0 0.0 0.0 0.0" type="mesh" mesh="left_knee_link"  />
              <geom name="left_knee_link_visual" pos="0 0 0" quat="1.0 0.0 0.0 0.0" material="white" type="mesh" mesh="left_knee_link" />
              <body name="left_ankle_pitch_link" pos="0 -9.4445E-05 -0.30001" quat="1.0 0.0 0.0 0.0">
                <joint name="left_ankle_pitch_joint" type="hinge" ref="0.0"  range="-0.87267 0.5236" axis="0 1 0" actuatorfrcrange="-50 50" class="ankle_motor"/>
                <inertial pos="-0.007269 0 0.011137" quat="1.0 0.0 0.0 0.0" mass="0.074" diaginertia="8.4e-06 1.89e-05 1.26e-05" />
                <geom name="left_ankle_pitch_link_collision" pos="0 0 0" quat="1.0 0.0 0.0 0.0" type="mesh" mesh="left_ankle_pitch_link"  />
                <geom name="left_ankle_pitch_link_visual" pos="0 0 0" quat="1.0 0.0 0.0 0.0" material="white" type="mesh" mesh="left_ankle_pitch_link" />
                <body name="left_ankle_roll_link" pos="0 0 -0.017558" quat="1.0 0.0 0.0 0.0">
                  <joint name="left_ankle_roll_joint" type="hinge" ref="0.0"  range="-0.2618 0.2618" axis="1 0 0" actuatorfrcrange="-50 50" class="ankle_motor"/>
                  <inertial pos="0.026505 0 -0.016425" quat="1.0 0.0 0.0 0.0" mass="0.608" diaginertia="0.0002231 0.0016161 0.0016667" />
                  <geom name="left_ankle_roll_link_collision_0" pos="-0.05 0.025 -0.03" quat="1.0 0.0 0.0 0.0" type="sphere" size="0.005"  />
                  <geom name="left_ankle_roll_link_collision_1" pos="-0.05 -0.025 -0.03" quat="1.0 0.0 0.0 0.0" type="sphere" size="0.005"  />
                  <geom name="left_ankle_roll_link_collision_2" pos="0.12 0.03 -0.03" quat="1.0 0.0 0.0 0.0" type="sphere" size="0.005"  />
                  <geom name="left_ankle_roll_link_collision_3" pos="0.12 -0.03 -0.03" quat="1.0 0.0 0.0 0.0" type="sphere" size="0.005"  />
                  <geom name="left_ankle_roll_link_visual" pos="0 0 0" quat="1.0 0.0 0.0 0.0" material="dark" type="mesh" mesh="left_ankle_roll_link" />
                </body>
              </body>
            </body>
          </body>
        </body>
      </body>
      <body name="right_hip_pitch_link" pos="0 -0.064452 -0.1027" quat="1.0 0.0 0.0 0.0">
        <joint name="right_hip_pitch_joint" type="hinge" ref="0.0"  range="-2.5307 2.8798" axis="0 1 0" actuatorfrcrange="-88 88" class="leg_motor"/>
        <inertial pos="0.002741 -0.047791 -0.02606" quat="1.0 0.0 0.0 0.0" mass="1.35" diaginertia="0.001811 0.0014193 0.0012812" />
        <geom name="right_hip_pitch_link_collision" pos="0 0 0" quat="1.0 0.0 0.0 0.0" type="mesh" mesh="right_hip_pitch_link"  />
        <geom name="right_hip_pitch_link_visual" pos="0 0 0" quat="1.0 0.0 0.0 0.0" material="dark" type="mesh" mesh="right_hip_pitch_link" />
        <body name="right_hip_roll_link" pos="0 -0.052 -0.030465" quat="0.9961786849744957 0.0 -0.08733858026373247 0.0">
          <joint name="right_hip_roll_joint" type="hinge" ref="0.0"  range="-2.9671 0.5236" axis="1 0 0" actuatorfrcrange="-88 88" class="leg_motor"/>
          <inertial pos="0.029812 0.001045 -0.087934" quat="1.0 0.0 0.0 0.0" mass="1.52" diaginertia="0.0023773 0.0024123 0.0016595" />
          <geom name="right_hip_roll_link_collision" pos="0 0 0" quat="1.0 0.0 0.0 0.0" type="mesh" mesh="right_hip_roll_link"  />
          <geom name="right_hip_roll_link_visual" pos="0 0 0" quat="1.0 0.0 0.0 0.0" material="white" type="mesh" mesh="right_hip_roll_link" />
          <body name="right_hip_yaw_link" pos="0.025001 0 -0.12412" quat="1.0 0.0 0.0 0.0">
            <joint name="right_hip_yaw_joint" type="hinge" ref="0.0"  range="-2.7576 2.7576" axis="0 0 1" actuatorfrcrange="-88 88" class="leg_motor"/>
            <inertial pos="-0.057709 0.010981 -0.15078" quat="1.0 0.0 0.0 0.0" mass="1.702" diaginertia="0.0057774 0.0076124 0.003149" />
            <geom name="right_hip_yaw_link_collision" pos="0 0 0" quat="1.0 0.0 0.0 0.0" type="mesh" mesh="right_hip_yaw_link"  />
            <geom name="right_hip_yaw_link_visual" pos="0 0 0" quat="1.0 0.0 0.0 0.0" material="white" type="mesh" mesh="right_hip_yaw_link" />
            <body name="right_knee_link" pos="-0.078273 -0.0021489 -0.17734" quat="0.9961786849744957 0.0 0.08733858026373247 0.0">
              <joint name="right_knee_joint" type="hinge" ref="0.0"  range="-0.087267 2.8798" axis="0 1 0" actuatorfrcrange="-139 139" class="leg_motor"/>
              <inertial pos="0.005457 -0.003964 -0.12074" quat="1.0 0.0 0.0 0.0" mass="1.932" diaginertia="0.011329 0.011277 0.0015168" />
              <geom name="right_knee_link_collision" pos="0 0 0" quat="1.0 0.0 0.0 0.0" type="mesh" mesh="right_knee_link"  />
              <geom name="right_knee_link_visual" pos="0 0 0" quat="1.0 0.0 0.0 0.0" material="white" type="mesh" mesh="right_knee_link" />
              <body name="right_ankle_pitch_link" pos="0 9.4445E-05 -0.30001" quat="1.0 0.0 0.0 0.0">
                <joint name="right_ankle_pitch_joint" type="hinge" ref="0.0"  range="-0.87267 0.5236" axis="0 1 0" actuatorfrcrange="-50 50" class="ankle_motor"/>
                <inertial pos="-0.007269 0 0.011137" quat="1.0 0.0 0.0 0.0" mass="0.074" diaginertia="8.4e-06 1.89e-05 1.26e-05" />
                <geom name="right_ankle_pitch_link_collision" pos="0 0 0" quat="1.0 0.0 0.0 0.0" type="mesh" mesh="right_ankle_pitch_link"  />
                <geom name="right_ankle_pitch_link_visual" pos="0 0 0" quat="1.0 0.0 0.0 0.0" material="white" type="mesh" mesh="right_ankle_pitch_link" />
                <body name="right_ankle_roll_link" pos="0 0 -0.017558" quat="1.0 0.0 0.0 0.0">
                  <joint name="right_ankle_roll_joint" type="hinge" ref="0.0"  range="-0.2618 0.2618" axis="1 0 0" actuatorfrcrange="-50 50" class="ankle_motor"/>
                  <inertial pos="0.026505 0 -0.016425" quat="1.0 0.0 0.0 0.0" mass="0.608" diaginertia="0.0002231 0.0016161 0.0016667" />
                  <geom name="right_ankle_roll_link_collision_0" pos="-0.05 0.025 -0.03" quat="1.0 0.0 0.0 0.0" type="sphere" size="0.005"  />
                  <geom name="right_ankle_roll_link_collision_1" pos="-0.05 -0.025 -0.03" quat="1.0 0.0 0.0 0.0" type="sphere" size="0.005"  />
                  <geom name="right_ankle_roll_link_collision_2" pos="0.12 0.03 -0.03" quat="1.0 0.0 0.0 0.0" type="sphere" size="0.005"  />
                  <geom name="right_ankle_roll_link_collision_3" pos="0.12 -0.03 -0.03" quat="1.0 0.0 0.0 0.0" type="sphere" size="0.005"  />
                  <geom name="right_ankle_roll_link_visual" pos="0 0 0" quat="1.0 0.0 0.0 0.0" material="dark" type="mesh" mesh="right_ankle_roll_link" />
                </body>
              </body>
            </body>
          </body>
        </body>
      </body>
      <body name="waist_yaw_link" pos="0 0 0" quat="1.0 0.0 0.0 0.0">
        <joint name="waist_yaw_joint" type="hinge" ref="0.0"  range="-2.618 2.618" axis="0 0 1" actuatorfrcrange="-88 88" class="torso_motor"/>
        <inertial pos="0.003494 0.000233 0.018034" quat="1.0 0.0 0.0 0.0" mass="0.214" diaginertia="0.00010673 0.00010422 0.0001625"/>
        <geom name="waist_yaw_link_visual" pos="0 0 0" quat="1.0 0.0 0.0 0.0" material="white" type="mesh" mesh="waist_yaw_link_rev_1_0" />
        <body name="waist_roll_link" pos="-0.0039635 0 0.044" quat="1.0 0.0 0.0 0.0">
          <joint name="waist_roll_joint" type="hinge" ref="0.0"  range="-0.52 0.52" axis="1 0 0" actuatorfrcrange="-50 50" class="torso_motor"/>
          <inertial pos="0 2.3E-05 0" quat="1.0 0.0 0.0 0.0" mass="0.086" diaginertia="7.079e-06 6.339e-06 8.245e-06" />
          <geom name="waist_roll_link_visual" pos="0 0 0" quat="1.0 0.0 0.0 0.0" material="white" type="mesh" mesh="waist_roll_link_rev_1_0" />
          <body name="torso_link" pos="0 0 0" quat="1.0 0.0 0.0 0.0">
            <joint name="waist_pitch_joint" type="hinge" ref="0.0"  range="-0.52 0.52" axis="0 1 0" actuatorfrcrange="-50 50" class="torso_motor"/>
            <inertial pos="0.000931 0.000346 0.15082" quat="1.0 0.0 0.0 0.0" mass="6.78" diaginertia="0.05905 0.047014 0.025652" />
            <geom name="torso_link_collision" pos="0 0 0" quat="1.0 0.0 0.0 0.0" type="mesh" mesh="torso_link_rev_1_0"  />
            <geom name="torso_link_visual" pos="0 0 0" quat="1.0 0.0 0.0 0.0" material="white" type="mesh" mesh="torso_link_rev_1_0" />
            <body name="logo_link" pos="0.0039635 0 -0.044" quat="1.0 0.0 0.0 0.0">
              <inertial pos="0 0 0" quat="1.0 0.0 0.0 0.0" mass="0.001" diaginertia="1e-07 1e-07 1e-07" />
              <geom name="logo_link_collision" pos="0 0 0" quat="1.0 0.0 0.0 0.0" type="mesh" mesh="logo_link"  />
              <geom name="logo_link_visual" pos="0 0 0" quat="1.0 0.0 0.0 0.0" material="dark" type="mesh" mesh="logo_link" />
            </body>
            <body name="head_link" pos="0.0039635 0 -0.044" quat="1.0 0.0 0.0 0.0">
              <inertial pos="0.005267 0.000299 0.449869" quat="1.0 0.0 0.0 0.0" mass="1.036" diaginertia="0.004085051 0.004185212 0.001807911" />
              <geom name="head_link_collision" pos="0 0 0" quat="1.0 0.0 0.0 0.0" type="mesh" mesh="head_link"  />
              <geom name="head_link_visual" pos="0 0 0" quat="1.0 0.0 0.0 0.0" material="dark" type="mesh" mesh="head_link" />
            </body>
            <body name="imu_in_torso" pos="-0.03959 -0.00224 0.14792" quat="1.0 0.0 0.0 0.0" />
            <body name="d435_link" pos="0.0576235 0.01753 0.42987" quat="0.9149596678498247 0.0 0.40354529635239006 0.0" />
            <body name="mid360_link" pos="0.0002835 0.00003 0.41618" quat="0.9997985784932998 0.0 0.020069938783589012 0.0" />
            <body name="left_shoulder_pitch_link" pos="0.0039563 0.10022 0.24778" quat="0.9902640743722195 0.13920148374281427 1.3872204401988457e-05 -9.868683842420437e-05">
              <joint name="left_shoulder_pitch_joint" type="hinge" ref="0.0"  range="-3.0892 2.6704" axis="0 1 0" actuatorfrcrange="-25 25" class="arm_motor"/>
              <inertial pos="0 0.035892 -0.011628" quat="1.0 0.0 0.0 0.0" mass="0.718" diaginertia="0.0004291 0.000453 0.000423" />
              <geom name="left_shoulder_pitch_link_collision" pos="0 0.04 -0.01" quat="0.7071067811865476 0.0 0.7071067811865475 0.0" type="cylinder" size="0.03 0.025"  />
              <geom name="left_shoulder_pitch_link_visual" pos="0 0 0" quat="1.0 0.0 0.0 0.0" material="white" type="mesh" mesh="left_shoulder_pitch_link" />
              <body name="left_shoulder_roll_link" pos="0 0.038 -0.013831" quat="0.9902682552548409 -0.1391717738427347 0.0 0.0">
                <joint name="left_shoulder_roll_joint" type="hinge" ref="0.0"  range="-1.5882 2.2515" axis="1 0 0" actuatorfrcrange="-25 25" class="arm_motor"/>
                <inertial pos="-0.000227 0.00727 -0.063243" quat="1.0 0.0 0.0 0.0" mass="0.643" diaginertia="0.0006177 0.0006912 0.0003894" />
                <geom name="left_shoulder_roll_link_collision" pos="-0.004 0.006 -0.053" quat="1.0 0.0 0.0 0.0" type="cylinder" size="0.03 0.015"  />
                <geom name="left_shoulder_roll_link_visual" pos="0 0 0" quat="1.0 0.0 0.0 0.0" material="white" type="mesh" mesh="left_shoulder_roll_link" />
                <body name="left_shoulder_yaw_link" pos="0 0.00624 -0.1032" quat="1.0 0.0 0.0 0.0">
                  <joint name="left_shoulder_yaw_joint" type="hinge" ref="0.0"  range="-2.618 2.618" axis="0 0 1" actuatorfrcrange="-25 25" class="arm_motor"/>
                  <inertial pos="0.010773 -0.002949 -0.072009" quat="1.0 0.0 0.0 0.0" mass="0.734" diaginertia="0.0009988 0.0010605 0.0004354" />
                  <geom name="left_shoulder_yaw_link_collision" pos="0 0 0" quat="1.0 0.0 0.0 0.0" type="mesh" mesh="left_shoulder_yaw_link"  />
                  <geom name="left_shoulder_yaw_link_visual" pos="0 0 0" quat="1.0 0.0 0.0 0.0" material="white" type="mesh" mesh="left_shoulder_yaw_link" />
                  <body name="left_elbow_link" pos="0.015783 0 -0.080518" quat="1.0 0.0 0.0 0.0">
                    <joint name="left_elbow_joint" type="hinge" ref="0.0"  range="-1.0472 2.0944" axis="0 1 0" actuatorfrcrange="-25 25" class="arm_motor"/>
                    <inertial pos="0.064956 0.004454 -0.010062" quat="1.0 0.0 0.0 0.0" mass="0.6" diaginertia="0.0002891 0.0004152 0.0004197" />
                    <geom name="left_elbow_link_collision" pos="0 0 0" quat="1.0 0.0 0.0 0.0" type="mesh" mesh="left_elbow_link"  />
                    <geom name="left_elbow_link_visual" pos="0 0 0" quat="1.0 0.0 0.0 0.0" material="white" type="mesh" mesh="left_elbow_link" />
                    <body name="left_wrist_roll_link" pos="0.100 0.00188791 -0.010" quat="1.0 0.0 0.0 0.0">
                      <joint name="left_wrist_roll_joint" type="hinge" ref="0.0"  range="-1.972222054 1.972222054" axis="1 0 0" actuatorfrcrange="-25 25" class="arm_motor"/>
                      <inertial pos="0.01713944778 0.00053759094 0.00000048864" quat="1.0 0.0 0.0 0.0" mass="0.08544498" diaginertia="4.821544023e-05 3.722899093e-05 5.482106541e-05" />
                      <geom name="left_wrist_roll_link_collision" pos="0 0 0" quat="1.0 0.0 0.0 0.0" type="mesh" mesh="left_wrist_roll_link"  />
                      <geom name="left_wrist_roll_link_visual" pos="0 0 0" quat="1.0 0.0 0.0 0.0" material="white" type="mesh" mesh="left_wrist_roll_link" />
                      <body name="left_wrist_pitch_link" pos="0.038 0 0" quat="1.0 0.0 0.0 0.0">
                        <joint name="left_wrist_pitch_joint" type="hinge" ref="0.0"  range="-1.614429558 1.614429558" axis="0 1 0" actuatorfrcrange="-5 5" class="wrist_motor"/>
                        <inertial pos="0.02299989837 -0.00111685314 -0.00111658096" quat="1.0 0.0 0.0 0.0" mass="0.48404956" diaginertia="0.00016579646273 0.0004295405741 0.00042953697654" />
                        <geom name="left_wrist_pitch_link_collision" pos="0 0 0" quat="1.0 0.0 0.0 0.0" type="mesh" mesh="left_wrist_pitch_link"  />
                        <geom name="left_wrist_pitch_link_visual" pos="0 0 0" quat="1.0 0.0 0.0 0.0" material="white" type="mesh" mesh="left_wrist_pitch_link" />
                        <body name="left_wrist_yaw_link" pos="0.046 0 0" quat="1.0 0.0 0.0 0.0">
                          <joint name="left_wrist_yaw_joint" type="hinge" ref="0.0"  range="-1.614429558 1.614429558" axis="0 0 1" actuatorfrcrange="-5 5" class="wrist_motor"/>
                          <inertial pos="0.02200381568 0.00049485096 0.00053861123" quat="1.0 0.0 0.0 0.0" mass="0.08457647" diaginertia="4.929128828e-05 5.973338134e-05 3.928083826e-05" />
                          <geom name="left_wrist_yaw_link_collision" pos="0 0 0" quat="1.0 0.0 0.0 0.0" type="mesh" mesh="left_wrist_yaw_link"  />
                          <geom name="left_wrist_yaw_link_visual" pos="0 0 0" quat="1.0 0.0 0.0 0.0" material="white" type="mesh" mesh="left_wrist_yaw_link" />
                          <body name="left_base_link" pos="0.0415 0 0" quat="3.17466847769116e-11 0.7071067812200985 -3.174668477389895e-11 0.7071067811529965">
                            <inertial pos="-0.000129826516506615 -0.00373209820390109 0.0826860453890524" quat="1.0 0.0 0.0 0.0" mass="0.62266" diaginertia="0.000221307823686699 0.00026513454780435 0.000132311385681939" />
                            <geom name="left_base_link_collision" pos="0 0 0" quat="1.0 0.0 0.0 0.0" type="mesh" mesh="left_base_link"  />
                            <geom name="left_base_link_visual" pos="0 0 0" quat="1.0 0.0 0.0 0.0" material="07" type="mesh" mesh="left_base_link" />
                            <body name="left_palm_force_sensor" pos="0.00036819 0.012296 0.1196" quat="-2.5973434669646147e-06 -2.597353007557415e-06 0.7071080798547033 0.707105482506466">
                              <inertial pos="-0.000120093335198468 0.000717297413647363 -0.000692889069965119" quat="1.0 0.0 0.0 0.0" mass="0.001" diaginertia="1.79237847416137e-07 5.01887324843558e-07 6.80017237748533e-07" />
                              <geom name="left_palm_force_sensor_collision" pos="0 0 0" quat="1.0 0.0 0.0 0.0" type="mesh" mesh="left_palm_force_sensor"  />
                              <geom name="left_palm_force_sensor_visual" pos="0 0 0" quat="1.0 0.0 0.0 0.0" material="04" type="mesh" mesh="left_palm_force_sensor" />
                            </body>
                            <body name="left_thumb_1" pos="0.0269 0.02101 0.0689" quat="1.0 0.0 0.0 0.0">
                              <joint name="left_thumb_1_joint" type="hinge" ref="0.0"  range="0 1.1641" axis="0 0 1" />
                              <inertial pos="0.000892587008927997 0.000344904925262568 0.00159994421521059" quat="1.0 0.0 0.0 0.0" mass="0.00746" diaginertia="1.2983519872666e-07 1.11222049064813e-07 7.03400599726425e-08" />
                              <geom name="left_thumb_1_collision" pos="0 0 0" quat="1.0 0.0 0.0 0.0" type="mesh" mesh="left_thumb_1"  />
                              <geom name="left_thumb_1_visual" pos="0 0 0" quat="1.0 0.0 0.0 0.0" material="07" type="mesh" mesh="left_thumb_1" />
                              <body name="left_thumb_2" pos="0.0073431 0.011232 0.0052" quat="0.09229342560032669 0.09229376461363124 -0.7010589829793177 -0.7010564078506132">
                                <joint name="left_thumb_2_joint" type="hinge" ref="0.0"  range="0 0.5864" axis="0 0 -1" />
                                <inertial pos="-0.0138338557330702 0.0119064253484683 -0.00884568682807551" quat="1.0 0.0 0.0 0.0" mass="0.04264" diaginertia="1.06992620749386e-06 9.94179895508654e-07 1.3509537005286e-06" />
                                <geom name="left_thumb_2_collision" pos="0 0 0" quat="1.0 0.0 0.0 0.0" type="mesh" mesh="left_thumb_2"  />
                                <geom name="left_thumb_2_visual" pos="0 0 0" quat="1.0 0.0 0.0 0.0" material="07" type="mesh" mesh="left_thumb_2" />
                                <body name="left_thumb_force_sensor_1" pos="-0.0087121 0.026305 -0.0089605" quat="0.40591704575620713 -0.5789932543344314 -0.4059155581314522 -0.5789911252053949">
                                  <inertial pos="1.66858232989106E-05 -1.15630711571557E-05 -0.00107124647646149" quat="1.0 0.0 0.0 0.0" mass="0.001" diaginertia="9.01122065715071e-09 4.94557964402789e-09 1.35651342806704e-08" />
                                  <geom name="left_thumb_force_sensor_1_collision" pos="0 0 0" quat="1.0 0.0 0.0 0.0" type="mesh" mesh="left_thumb_force_sensor_1"  />
                                  <geom name="left_thumb_force_sensor_1_visual" pos="0 0 0" quat="1.0 0.0 0.0 0.0" material="04" type="mesh" mesh="left_thumb_force_sensor_1" />
                                </body>
                                <body name="left_thumb_3" pos="-0.031403 0.021069 -0.001299" quat="1.0 0.0 0.0 0.0">
                                  <joint name="left_thumb_3_joint" type="hinge" ref="0.0"  range="0 0.5" axis="0 0 -1" />
                                  <inertial pos="-0.0108800191783186 0.00425952831010942 -0.0076501712330704" quat="1.0 0.0 0.0 0.0" mass="0.01501" diaginertia="5.19553148414743e-07 5.03386725498716e-07 5.33624332749317e-07" />
                                  <geom name="left_thumb_3_collision" pos="0 0 0" quat="1.0 0.0 0.0 0.0" type="mesh" mesh="left_thumb_3"  />
                                  <geom name="left_thumb_3_visual" pos="0 0 0" quat="1.0 0.0 0.0 0.0" material="07" type="mesh" mesh="left_thumb_3" />
                                  <body name="left_thumb_force_sensor_2" pos="-0.011771 0.01699 -0.0077514" quat="0.4283023283587978 -0.5627657407107441 -0.4281754297033958 -0.5625990028457502">
                                    <inertial pos="2.43332410831479E-05 -5.44992472824302E-05 -0.00109137310434532" quat="1.0 0.0 0.0 0.0" mass="0.001" diaginertia="3.34748296277895e-10 3.35821649138781e-10 5.88578470286886e-10" />
                                    <geom name="left_thumb_force_sensor_2_collision" pos="0 0 0" quat="1.0 0.0 0.0 0.0" type="mesh" mesh="left_thumb_force_sensor_2"  />
                                    <geom name="left_thumb_force_sensor_2_visual" pos="0 0 0" quat="1.0 0.0 0.0 0.0" material="04" type="mesh" mesh="left_thumb_force_sensor_2" />
                                  </body>
                                  <body name="left_thumb_4" pos="-0.021903 0.012816 -0.0003" quat="1.0 0.0 0.0 0.0">
                                    <joint name="left_thumb_4_joint" type="hinge" ref="0.0"  range="0 3.14" axis="0 0 -1" />
                                    <inertial pos="-0.0163213563394194 0.00521928641987035 -0.00735104436106706" quat="1.0 0.0 0.0 0.0" mass="0.00972" diaginertia="5.94897206401284e-07 7.79202349429445e-07 8.99824190088835e-07" />
                                    <geom name="left_thumb_4_collision" pos="0 0 0" quat="1.0 0.0 0.0 0.0" type="mesh" mesh="left_thumb_4"  />
                                    <geom name="left_thumb_4_visual" pos="0 0 0" quat="1.0 0.0 0.0 0.0" material="07" type="mesh" mesh="left_thumb_4" />
                                    <body name="left_thumb_force_sensor_3" pos="-0.014598 0.014721 -0.0073103" quat="0.3484320413094421 -0.6153018221135867 -0.34843288108528664 -0.6152993642701424">
                                      <inertial pos="-1.23189696923445E-05 0.000195538975680837 -0.000792005365136905" quat="1.0 0.0 0.0 0.0" mass="0.001" diaginertia="5.41173490291494e-09 2.55896079923591e-09 7.82764624814665e-09" />
                                      <geom name="left_thumb_force_sensor_3_collision" pos="0 0 0" quat="1.0 0.0 0.0 0.0" type="mesh" mesh="left_thumb_force_sensor_3"  />
                                      <geom name="left_thumb_force_sensor_3_visual" pos="0 0 0" quat="1.0 0.0 0.0 0.0" material="04" type="mesh" mesh="left_thumb_force_sensor_3" />
                                    </body>
                                    <body name="left_thumb_force_sensor_4" pos="-0.028987 0.017301 -0.0073513" quat="-0.3562181472105803 0.6108269724884516 -0.35621555044875364 -0.6108269172989553">
                                      <inertial pos="-8.78777579448042E-07 -0.000270130629645191 -0.00100448285176212" quat="1.0 0.0 0.0 0.0" mass="0.001" diaginertia="8.13578898809676e-11 1.70778531226233e-10 2.11644262323665e-10" />
                                      <geom name="left_thumb_force_sensor_4_collision" pos="0 0 0" quat="1.0 0.0 0.0 0.0" type="mesh" mesh="left_thumb_force_sensor_4"  />
                                      <geom name="left_thumb_force_sensor_4_visual" pos="0 0 0" quat="1.0 0.0 0.0 0.0" material="04" type="mesh" mesh="left_thumb_force_sensor_4" />
                                    </body>
                                  </body>
                                </body>
                              </body>
                            </body>
                            <body name="left_index_1" pos="0.038679 0.00056467 0.1564" quat="0.5086465971930475 0.49119935114104324 -0.49120115542032033 -0.5086484655597555">
                              <joint name="left_index_1_joint" type="hinge" ref="0.0"  range="0 1.4381" axis="0 0 1" />
                              <inertial pos="-0.00219464981659673 0.0127400599495518 0.00664960432625117" quat="1.0 0.0 0.0 0.0" mass="0.02841" diaginertia="1.13152958548118e-06 5.50274101364838e-07 1.17474430240968e-06" />
                              <geom name="left_index_1_collision" pos="0 0 0" quat="1.0 0.0 0.0 0.0" type="mesh" mesh="left_index_1"  />
                              <geom name="left_index_1_visual" pos="0 0 0" quat="1.0 0.0 0.0 0.0" material="07" type="mesh" mesh="left_index_1" />
                              <body name="left_index_force_sensor_1" pos="-0.012046 0.019649 0.006651" quat="0.7016863628765856 -0.0622872870051811 -0.7043581187319252 -0.08738525394473562">
                                <inertial pos="-4.39980862962375E-06 0.000116492429592427 -0.000567426247601172" quat="1.0 0.0 0.0 0.0" mass="0.001" diaginertia="3.38062498899254e-09 1.96425205496783e-09 5.28129594144099e-09" />
                                <geom name="left_index_force_sensor_1_collision" pos="0 0 0" quat="1.0 0.0 0.0 0.0" type="mesh" mesh="left_index_force_sensor_1"  />
                                <geom name="left_index_force_sensor_1_visual" pos="0 0 0" quat="1.0 0.0 0.0 0.0" material="04" type="mesh" mesh="left_index_force_sensor_1" />
                              </body>
                              <body name="left_index_2" pos="-0.0034259 0.032596 0.00055" quat="1.0 0.0 0.0 0.0">
                                <joint name="left_index_2_joint" type="hinge" ref="0.0"  range="0 3.14" axis="0 0 1" />
                                <inertial pos="0.000533233960149537 0.0253408354610482 0.00609265194430511" quat="1.0 0.0 0.0 0.0" mass="0.01218" diaginertia="2.11152230822014e-06 3.70467679203513e-07 2.14356971717263e-06" />
                                <geom name="left_index_2_collision" pos="0 0 0" quat="1.0 0.0 0.0 0.0" type="mesh" mesh="left_index_2"  />
                                <geom name="left_index_2_visual" pos="0 0 0" quat="1.0 0.0 0.0 0.0" material="07" type="mesh" mesh="left_index_2" />
                                <body name="left_index_force_sensor_2" pos="-0.0081655 0.037446 0.0060795" quat="0.6985363631756389 0.13558998152679413 -0.6939851763727715 0.1097582853627399">
                                  <inertial pos="-3.92383751107728E-06 0.000206469730308023 -0.000722888601662641" quat="1.0 0.0 0.0 0.0" mass="0.001" diaginertia="4.7987768166369e-09 2.43957953886802e-09 7.12568463704975e-09" />
                                  <geom name="left_index_force_sensor_2_collision" pos="0 0 0" quat="1.0 0.0 0.0 0.0" type="mesh" mesh="left_index_force_sensor_2"  />
                                  <geom name="left_index_force_sensor_2_visual" pos="0 0 0" quat="1.0 0.0 0.0 0.0" material="04" type="mesh" mesh="left_index_force_sensor_2" />
                                </body>
                                <body name="left_index_force_sensor_3" pos="-0.0086237 0.052572 0.0060954" quat="0.6587426851508513 -0.2267245629183824 -0.6697731379226735 -0.25701749171394966">
                                  <inertial pos="2.48712002496876E-05 -0.000345284176963695 -0.00133798867886123" quat="1.0 0.0 0.0 0.0" mass="0.001" diaginertia="1.31976081706364e-10 2.53434470713008e-10 2.80536896961268e-10" />
                                  <geom name="left_index_force_sensor_3_collision" pos="0 0 0" quat="1.0 0.0 0.0 0.0" type="mesh" mesh="left_index_force_sensor_3"  />
                                  <geom name="left_index_force_sensor_3_visual" pos="0 0 0" quat="1.0 0.0 0.0 0.0" material="04" type="mesh" mesh="left_index_force_sensor_3" />
                                </body>
                              </body>
                            </body>
                            <body name="left_middle_1" pos="0.0171 0.00056467 0.157" quat="0.4999981633974483 0.49999999999662686 -0.5000018366025516 -0.49999999999662686">
                              <joint name="left_middle_1_joint" type="hinge" ref="0.0"  range="0 1.4381" axis="0 0 1" />
                              <inertial pos="-0.00219464961590674 0.0127400600036114 0.00664960428412462" quat="1.0 0.0 0.0 0.0" mass="0.02841" diaginertia="1.13152961123076e-06 5.50274106824469e-07 1.17474433485984e-06" />
                              <geom name="left_middle_1_collision" pos="0 0 0" quat="1.0 0.0 0.0 0.0" type="mesh" mesh="left_middle_1"  />
                              <geom name="left_middle_1_visual" pos="0 0 0" quat="1.0 0.0 0.0 0.0" material="07" type="mesh" mesh="left_middle_1" />
                              <body name="left_middle_force_sensor_1" pos="-0.012046 0.019649 0.006651" quat="0.7031337401387545 -0.07484564391185897 -0.7031354722727027 -0.074843708471379">
                                <inertial pos="-2.38805233421235E-07 0.00011657525419928 -0.00056742615707274" quat="1.0 0.0 0.0 0.0" mass="0.001" diaginertia="3.3824362190208e-09 1.96244127906411e-09 5.28129636598898e-09" />
                                <geom name="left_middle_force_sensor_1_collision" pos="0 0 0" quat="1.0 0.0 0.0 0.0" type="mesh" mesh="left_middle_force_sensor_1"  />
                                <geom name="left_middle_force_sensor_1_visual" pos="0 0 0" quat="1.0 0.0 0.0 0.0" material="04" type="mesh" mesh="left_middle_force_sensor_1" />
                              </body>
                              <body name="left_middle_2" pos="-0.0034259 0.032596 0.00055" quat="1.0 0.0 0.0 0.0">
                                <joint name="left_middle_2_joint" type="hinge" ref="0.0"  range="0 3.14" axis="0 0 1" />
                                <inertial pos="-9.24135364655104E-05 0.0270345152816558 0.00610059049321496" quat="1.0 0.0 0.0 0.0" mass="0.01561" diaginertia="2.58658045501346e-06 4.10327347278853e-07 2.62954290013629e-06" />
                                <geom name="left_middle_2_collision" pos="0 0 0" quat="1.0 0.0 0.0 0.0" type="mesh" mesh="left_middle_2"  />
                                <geom name="left_middle_2_visual" pos="0 0 0" quat="1.0 0.0 0.0 0.0" material="07" type="mesh" mesh="left_middle_2" />
                                <body name="left_middle_force_sensor_2" pos="-0.009086 0.040962 0.0061003" quat="0.6948582868023875 0.1310414841854292 -0.6948579320683002 0.13104405719564932">
                                  <inertial pos="6.77351601335863E-07 2.94313228783732E-05 -0.000722425776846891" quat="1.0 0.0 0.0 0.0" mass="0.001" diaginertia="5.04148765936938e-09 2.56777987860697e-09 7.49457837348363e-09" />
                                  <geom name="left_middle_force_sensor_2_collision" pos="0 0 0" quat="1.0 0.0 0.0 0.0" type="mesh" mesh="left_middle_force_sensor_2"  />
                                  <geom name="left_middle_force_sensor_2_visual" pos="0 0 0" quat="1.0 0.0 0.0 0.0" material="04" type="mesh" mesh="left_middle_force_sensor_2" />
                                </body>
                                <body name="left_middle_force_sensor_3" pos="-0.0098294 0.056051 0.0061006" quat="0.6672877229845224 -0.23393803311104103 -0.667288703221979 -0.23393562783509128">
                                  <inertial pos="-8.06940798625533E-08 -0.000365444698807449 -0.0012768401530425" quat="1.0 0.0 0.0 0.0" mass="0.001" diaginertia="1.27227716200634e-10 2.43691020872239e-10 2.75875028961867e-10" />
                                  <geom name="left_middle_force_sensor_3_collision" pos="0 0 0" quat="1.0 0.0 0.0 0.0" type="mesh" mesh="left_middle_force_sensor_3"  />
                                  <geom name="left_middle_force_sensor_3_visual" pos="0 0 0" quat="1.0 0.0 0.0 0.0" material="04" type="mesh" mesh="left_middle_force_sensor_3" />
                                </body>
                              </body>
                            </body>
                            <body name="left_ring_1" pos="-0.0045302 0.00056467 0.15683" quat="0.48672806252019357 0.5129268530236907 -0.5129287371126852 -0.4867298503754804">
                              <joint name="left_ring_1_joint" type="hinge" ref="0.0"  range="0 1.4381" axis="0 0 1" />
                              <inertial pos="-0.0021946507104972 0.0127400598730178 0.00664960488600091" quat="1.0 0.0 0.0 0.0" mass="0.02841" diaginertia="1.13152930818392e-06 5.5027409300137e-07 1.17474396570232e-06" />
                              <geom name="left_ring_1_collision" pos="0 0 0" quat="1.0 0.0 0.0 0.0" type="mesh" mesh="left_ring_1"  />
                              <geom name="left_ring_1_visual" pos="0 0 0" quat="1.0 0.0 0.0 0.0" material="07" type="mesh" mesh="left_ring_1" />
                              <body name="left_ring_force_sensor_1" pos="-0.012046 0.019649 0.006651" quat="0.7048872569314628 -0.09366177587157093 -0.7008762873208181 -0.05598085947542597">
                                <inertial pos="6.00203522563292E-06 0.000116421389792051 -0.000567426346187727" quat="1.0 0.0 0.0 0.0" mass="0.001" diaginertia="3.37837011170993e-09 1.96650618264834e-09 5.28129521919661e-09" />
                                <geom name="left_ring_force_sensor_1_collision" pos="0 0 0" quat="1.0 0.0 0.0 0.0" type="mesh" mesh="left_ring_force_sensor_1"  />
                                <geom name="left_ring_force_sensor_1_visual" pos="0 0 0" quat="1.0 0.0 0.0 0.0" material="04" type="mesh" mesh="left_ring_force_sensor_1" />
                              </body>
                              <body name="left_ring_2" pos="-0.0034259 0.032596 0.00055" quat="1.0 0.0 0.0 0.0">
                                <joint name="left_ring_2_joint" type="hinge" ref="0.0"  range="0 3.14" axis="0 0 1" />
                                <inertial pos="0.000533229899902066 0.0253408208152093 0.00609266034565059" quat="1.0 0.0 0.0 0.0" mass="0.01281" diaginertia="2.1115233491356e-06 3.70467946466243e-07 2.14357084931758e-06" />
                                <geom name="left_ring_2_collision" pos="0 0 0" quat="1.0 0.0 0.0 0.0" type="mesh" mesh="left_ring_2"  />
                                <geom name="left_ring_2_visual" pos="0 0 0" quat="1.0 0.0 0.0 0.0" material="07" type="mesh" mesh="left_ring_2" />
                                <body name="left_ring_force_sensor_2" pos="-0.0081655 0.037446 0.0060795" quat="0.6926940779612758 0.10325726483388648 -0.6995270112713035 0.14203806573675992">
                                  <inertial pos="1.52347834254662E-05 0.000205944196161212 -0.000722888366336771" quat="1.0 0.0 0.0 0.0" mass="0.001" diaginertia="4.79445247032036e-09 2.4439035683217e-09 7.12568419691745e-09" />
                                  <geom name="left_ring_force_sensor_2_collision" pos="0 0 0" quat="1.0 0.0 0.0 0.0" type="mesh" mesh="left_ring_force_sensor_2"  />
                                  <geom name="left_ring_force_sensor_2_visual" pos="0 0 0" quat="1.0 0.0 0.0 0.0" material="04" type="mesh" mesh="left_ring_force_sensor_2" />
                                </body>
                                <body name="left_ring_force_sensor_3" pos="-0.0086237 0.052572 0.0060954" quat="0.6722998401140955 -0.26448739397172133 -0.6557793407585868 -0.21911823211874054">
                                  <inertial pos="-1.45503931299751E-05 -0.000345866634044262 -0.00133798468297447" quat="1.0 0.0 0.0 0.0" mass="0.001" diaginertia="1.32269553548932e-10 2.53144226946973e-10 2.80539791710119e-10" />
                                  <geom name="left_ring_force_sensor_3_collision" pos="0 0 0" quat="1.0 0.0 0.0 0.0" type="mesh" mesh="left_ring_force_sensor_3"  />
                                  <geom name="left_ring_force_sensor_3_visual" pos="0 0 0" quat="1.0 0.0 0.0 0.0" material="04" type="mesh" mesh="left_ring_force_sensor_3" />
                                </body>
                              </body>
                            </body>
                            <body name="left_little_1" pos="-0.025916 0.00056467 0.15365" quat="0.4731501456336671 0.5254779758318021 -0.5254799060237296 -0.47315188361438865">
                              <joint name="left_little_1_joint" type="hinge" ref="0.0"  range="0 1.4381" axis="0 0 1" />
                              <inertial pos="-0.00219465215954852 0.0127400596467728 0.00664960556534563" quat="1.0 0.0 0.0 0.0" mass="0.02841" diaginertia="1.13152896112829e-06 5.50274069155466e-07 1.17474354144948e-06" />
                              <geom name="left_little_1_collision" pos="0 0 0" quat="1.0 0.0 0.0 0.0" type="mesh" mesh="left_little_1"  />
                              <geom name="left_little_1_visual" pos="0 0 0" quat="1.0 0.0 0.0 0.0" material="07" type="mesh" mesh="left_little_1" />
                              <body name="left_little_force_sensor_1" pos="-0.012046 0.019649 0.006651" quat="0.7061323170733271 -0.11237447776128712 -0.6981204574179737 -0.03710733710536651">
                                <inertial pos="1.22242688521124E-05 0.00011593285335415 -0.000567426208209446" quat="1.0 0.0 0.0 0.0" mass="0.001" diaginertia="3.36621610386636e-09 1.97866156369579e-09 5.28129655313466e-09" />
                                <geom name="left_little_force_sensor_1_collision" pos="0 0 0" quat="1.0 0.0 0.0 0.0" type="mesh" mesh="left_little_force_sensor_1"  />
                                <geom name="left_little_force_sensor_1_visual" pos="0 0 0" quat="1.0 0.0 0.0 0.0" material="04" type="mesh" mesh="left_little_force_sensor_1" />
                              </body>
                              <body name="left_little_2" pos="-0.0034259 0.032596 0.00055" quat="1.0 0.0 0.0 0.0">
                                <joint name="left_little_2_joint" type="hinge" ref="0.0"  range="0 3.14" axis="0 0 1" />
                                <inertial pos="0.00142964313557047 0.0206393899153543 0.00609979950240341" quat="1.0 0.0 0.0 0.0" mass="0.00957" diaginertia="1.14691427718982e-06 2.66171126920969e-07 1.15054232943374e-06" />
                                <geom name="left_little_2_collision" pos="0 0 0" quat="1.0 0.0 0.0 0.0" type="mesh" mesh="left_little_2"  />
                                <geom name="left_little_2_visual" pos="0 0 0" quat="1.0 0.0 0.0 0.0" material="07" type="mesh" mesh="left_little_2" />
                                <body name="left_little_force_sensor_2" pos="-0.0064514 0.027683 0.0061172" quat="0.6890462575198304 0.08142044402691145 -0.7024036694912645 0.15879247897045567">
                                  <inertial pos="-1.80617029852947E-05 -0.000118388090627967 -0.000773722865239856" quat="1.0 0.0 0.0 0.0" mass="0.001" diaginertia="5.36044739120519e-09 2.78880843363446e-09 8.00957473963534e-09" />
                                  <geom name="left_little_force_sensor_2_collision" pos="0 0 0" quat="1.0 0.0 0.0 0.0" type="mesh" mesh="left_little_force_sensor_2"  />
                                  <geom name="left_little_force_sensor_2_visual" pos="0 0 0" quat="1.0 0.0 0.0 0.0" material="04" type="mesh" mesh="left_little_force_sensor_2" />
                                </body>
                                <body name="left_little_force_sensor_3" pos="-0.0063973 0.042707 0.0061154" quat="0.6787722837118708 -0.28913267010489596 -0.6452926082510165 -0.1981613879624003">
                                  <inertial pos="-6.37037929382966E-05 -0.000437210532086563 -0.00112816117341033" quat="1.0 0.0 0.0 0.0" mass="0.001" diaginertia="1.11591596284104e-10 2.17206534672885e-10 2.52052305204087e-10" />
                                  <geom name="left_little_force_sensor_3_collision" pos="0 0 0" quat="1.0 0.0 0.0 0.0" type="mesh" mesh="left_little_force_sensor_3"  />
                                  <geom name="left_little_force_sensor_3_visual" pos="0 0 0" quat="1.0 0.0 0.0 0.0" material="04" type="mesh" mesh="left_little_force_sensor_3" />
                                </body>
                              </body>
                            </body>
                          </body>
                        </body>
                      </body>
                    </body>
                  </body>
                </body>
              </body>
            </body>
            <body name="right_shoulder_pitch_link" pos="0.0039563 -0.10021 0.24778" quat="0.9902640743722195 -0.13920148374281427 1.3872204401988457e-05 9.868683842420437e-05">
              <joint name="right_shoulder_pitch_joint" type="hinge" ref="0.0"  range="-3.0892 2.6704" axis="0 1 0" actuatorfrcrange="-25 25" class="arm_motor"/>
              <inertial pos="0 -0.035892 -0.011628" quat="1.0 0.0 0.0 0.0" mass="0.718" diaginertia="0.0004291 0.000453 0.000423" />
              <geom name="right_shoulder_pitch_link_collision" pos="0 -0.04 -0.01" quat="0.7071067811865476 0.0 0.7071067811865475 0.0" type="cylinder" size="0.03 0.025"  />
              <geom name="right_shoulder_pitch_link_visual" pos="0 0 0" quat="1.0 0.0 0.0 0.0" material="white" type="mesh" mesh="right_shoulder_pitch_link" />
              <body name="right_shoulder_roll_link" pos="0 -0.038 -0.013831" quat="0.9902682552548409 0.1391717738427347 0.0 0.0">
                <joint name="right_shoulder_roll_joint" type="hinge" ref="0.0"  range="-2.2515 1.5882" axis="1 0 0" actuatorfrcrange="-25 25" class="arm_motor"/>
                <inertial pos="-0.000227 -0.00727 -0.063243" quat="1.0 0.0 0.0 0.0" mass="0.643" diaginertia="0.0006177 0.0006912 0.0003894" />
                <geom name="right_shoulder_roll_link_collision" pos="-0.004 -0.006 -0.053" quat="1.0 0.0 0.0 0.0" type="cylinder" size="0.03 0.015"  />
                <geom name="right_shoulder_roll_link_visual" pos="0 0 0" quat="1.0 0.0 0.0 0.0" material="white" type="mesh" mesh="right_shoulder_roll_link" />
                <body name="right_shoulder_yaw_link" pos="0 -0.00624 -0.1032" quat="1.0 0.0 0.0 0.0">
                  <joint name="right_shoulder_yaw_joint" type="hinge" ref="0.0"  range="-2.618 2.618" axis="0 0 1" actuatorfrcrange="-25 25" class="arm_motor"/>
                  <inertial pos="0.010773 0.002949 -0.072009" quat="1.0 0.0 0.0 0.0" mass="0.734" diaginertia="0.0009988 0.0010605 0.0004354" />
                  <geom name="right_shoulder_yaw_link_collision" pos="0 0 0" quat="1.0 0.0 0.0 0.0" type="mesh" mesh="right_shoulder_yaw_link"  />
                  <geom name="right_shoulder_yaw_link_visual" pos="0 0 0" quat="1.0 0.0 0.0 0.0" material="white" type="mesh" mesh="right_shoulder_yaw_link" />
                  <body name="right_elbow_link" pos="0.015783 0 -0.080518" quat="1.0 0.0 0.0 0.0">
                    <joint name="right_elbow_joint" type="hinge" ref="0.0"  range="-1.0472 2.0944" axis="0 1 0" actuatorfrcrange="-25 25" class="arm_motor"/>
                    <inertial pos="0.064956 -0.004454 -0.010062" quat="1.0 0.0 0.0 0.0" mass="0.6" diaginertia="0.0002891 0.0004152 0.0004197" />
                    <geom name="right_elbow_link_collision" pos="0 0 0" quat="1.0 0.0 0.0 0.0" type="mesh" mesh="right_elbow_link"  />
                    <geom name="right_elbow_link_visual" pos="0 0 0" quat="1.0 0.0 0.0 0.0" material="white" type="mesh" mesh="right_elbow_link" />
                    <body name="right_wrist_roll_link" pos="0.100 -0.00188791 -0.010" quat="1.0 0.0 0.0 0.0">
                      <joint name="right_wrist_roll_joint" type="hinge" ref="0.0"  range="-1.972222054 1.972222054" axis="1 0 0" actuatorfrcrange="-25 25" class="arm_motor"/>
                      <inertial pos="0.01713944778 -0.00053759094 0.00000048864" quat="1.0 0.0 0.0 0.0" mass="0.08544498" diaginertia="4.821544023e-05 3.722899093e-05 5.482106541e-05" />
                      <geom name="right_wrist_roll_link_collision" pos="0 0 0" quat="1.0 0.0 0.0 0.0" type="mesh" mesh="right_wrist_roll_link"  />
                      <geom name="right_wrist_roll_link_visual" pos="0 0 0" quat="1.0 0.0 0.0 0.0" material="white" type="mesh" mesh="right_wrist_roll_link" />
                      <body name="right_wrist_pitch_link" pos="0.038 0 0" quat="1.0 0.0 0.0 0.0">
                        <joint name="right_wrist_pitch_joint" type="hinge" ref="0.0"  range="-1.614429558 1.614429558" axis="0 1 0" actuatorfrcrange="-5 5" class="wrist_motor"/>
                        <inertial pos="0.02299989837 0.00111685314 -0.00111658096" quat="1.0 0.0 0.0 0.0" mass="0.48404956" diaginertia="0.00016579646273 0.0004295405741 0.00042953697654" />
                        <geom name="right_wrist_pitch_link_collision" pos="0 0 0" quat="1.0 0.0 0.0 0.0" type="mesh" mesh="right_wrist_pitch_link"  />
                        <geom name="right_wrist_pitch_link_visual" pos="0 0 0" quat="1.0 0.0 0.0 0.0" material="white" type="mesh" mesh="right_wrist_pitch_link" />
                        <body name="right_wrist_yaw_link" pos="0.046 0 0" quat="1.0 0.0 0.0 0.0">
                          <joint name="right_wrist_yaw_joint" type="hinge" ref="0.0"  range="-1.614429558 1.614429558" axis="0 0 1" actuatorfrcrange="-5 5" class="wrist_motor"/>
                          <inertial pos="0.02200381568 -0.00049485096 0.00053861123" quat="1.0 0.0 0.0 0.0" mass="0.08457647" diaginertia="4.929128828e-05 5.973338134e-05 3.928083826e-05" />
                          <geom name="right_wrist_yaw_link_collision" pos="0 0 0" quat="1.0 0.0 0.0 0.0" type="mesh" mesh="right_wrist_yaw_link"  />
                          <geom name="right_wrist_yaw_link_visual" pos="0 0 0" quat="1.0 0.0 0.0 0.0" material="white" type="mesh" mesh="right_wrist_yaw_link" />
                          <body name="right_base_link" pos="0.0415 0 0" quat="0.7071067812200985 0.0 0.7071067811529965 0.0">
                            <inertial pos="4.56066702604653E-05 -0.003106244650993 0.0721752784828355" quat="1.0 0.0 0.0 0.0" mass="0.62266" diaginertia="0.000238088630601122 0.00028210406583092 0.000154836898082308" />
                            <geom name="right_base_link_collision" pos="0 0 0" quat="1.0 0.0 0.0 0.0" type="mesh" mesh="right_base_link"  />
                            <geom name="right_base_link_visual" pos="0 0 0" quat="1.0 0.0 0.0 0.0" material="1" type="mesh" mesh="right_base_link" />
                            <body name="right_palm_force_sensor" pos="-0.00036819 0.012296 0.1196" quat="-2.5973434669646147e-06 -2.597353007557415e-06 -0.7071080798547033 -0.707105482506466">
                              <inertial pos="0.000120426871221421 0.000717269582936034 -0.0006928935004962" quat="1.0 0.0 0.0 0.0" mass="0.001" diaginertia="1.792409847502e-07 5.01925280756008e-07 6.80058307355101e-07" />
                              <geom name="right_palm_force_sensor_collision" pos="0 0 0" quat="1.0 0.0 0.0 0.0" type="mesh" mesh="right_palm_force_sensor"  />
                              <geom name="right_palm_force_sensor_visual" pos="0 0 0" quat="1.0 0.0 0.0 0.0" material="04" type="mesh" mesh="right_palm_force_sensor" />
                            </body>
                            <body name="right_thumb_1" pos="-0.0269 0.02101 0.0689" quat="1.0 0.0 0.0 0.0">
                              <joint name="right_thumb_1_joint" type="hinge" ref="0.0"  range="0 1.1641" axis="0 0 -1" />
                              <inertial pos="-0.000892586815740379 0.000344905600937098 0.00159994421661698" quat="1.0 0.0 0.0 0.0" mass="0.00746" diaginertia="1.29835194524364e-07 1.11222050936534e-07 7.03400601569091e-08" />
                              <geom name="right_thumb_1_collision" pos="0 0 0" quat="1.0 0.0 0.0 0.0" type="mesh" mesh="right_thumb_1"  />
                              <geom name="right_thumb_1_visual" pos="0 0 0" quat="1.0 0.0 0.0 0.0" material="1" type="mesh" mesh="right_thumb_1" />
                              <body name="right_thumb_2" pos="-0.0079252 0.0090599 0.0052" quat="0.09229342560032669 0.09229376461363124 0.7010589829793177 0.7010564078506132">
                                <joint name="right_thumb_2_joint" type="hinge" ref="0.0"  range="0 0.5864" axis="0 0 1" />
                                <inertial pos="0.0138310184561186 0.0119153040965892 -0.0066040787609158" quat="1.0 0.0 0.0 0.0" mass="0.04264" diaginertia="1.07086820134242e-06 9.9489890406106e-07 1.35184010899012e-06" />
                                <geom name="right_thumb_2_collision" pos="0 0 0" quat="1.0 0.0 0.0 0.0" type="mesh" mesh="right_thumb_2"  />
                                <geom name="right_thumb_2_visual" pos="0 0 0" quat="1.0 0.0 0.0 0.0" material="1" type="mesh" mesh="right_thumb_2" />
                                <body name="right_thumb_3" pos="0.031403 0.021069 0.00095" quat="1.0 0.0 0.0 0.0">
                                  <joint name="right_thumb_3_joint" type="hinge" ref="0.0"  range="0 0.5" axis="0 0 1" />
                                  <inertial pos="0.0108798353899717 0.0042597051968735 -0.00764637401672714" quat="1.0 0.0 0.0 0.0" mass="0.01501" diaginertia="5.19560132472211e-07 5.03378983794322e-07 5.33618730069293e-07" />
                                  <geom name="right_thumb_3_collision" pos="0 0 0" quat="1.0 0.0 0.0 0.0" type="mesh" mesh="right_thumb_3"  />
                                  <geom name="right_thumb_3_visual" pos="0 0 0" quat="1.0 0.0 0.0 0.0" material="1" type="mesh" mesh="right_thumb_3" />
                                  <body name="right_thumb_force_sensor_2" pos="0.011771 0.01699 -0.0077514" quat="-0.5626005760842531 0.42817336254651645 0.5627673134831211 0.4283002618143799">
                                    <inertial pos="2.43300294987259E-05 5.45016031029619E-05 -0.00109137669633625" quat="1.0 0.0 0.0 0.0" mass="0.001" diaginertia="3.34747183285769e-10 3.3582079154486e-10 5.8857712310973e-10" />
                                    <geom name="right_thumb_force_sensor_2_collision" pos="0 0 0" quat="1.0 0.0 0.0 0.0" type="mesh" mesh="right_thumb_force_sensor_2"  />
                                    <geom name="right_thumb_force_sensor_2_visual" pos="0 0 0" quat="1.0 0.0 0.0 0.0" material="04" type="mesh" mesh="right_thumb_force_sensor_2" />
                                  </body>
                                  <body name="right_thumb_4" pos="0.021903 0.012816 -0.0003" quat="1.0 0.0 0.0 0.0">
                                    <joint name="right_thumb_4_joint" type="hinge" ref="0.0"  range="0 3.14" axis="0 0 1" />
                                    <inertial pos="0.0163213285767181 0.00521948646562768 -0.00735105906992692" quat="1.0 0.0 0.0 0.0" mass="0.00972" diaginertia="5.94898170313626e-07 7.79213727447204e-07 8.99837239850073e-07" />
                                    <geom name="right_thumb_4_collision" pos="0 0 0" quat="1.0 0.0 0.0 0.0" type="mesh" mesh="right_thumb_4"  />
                                    <geom name="right_thumb_4_visual" pos="0 0 0" quat="1.0 0.0 0.0 0.0" material="1" type="mesh" mesh="right_thumb_4" />
                                    <body name="right_thumb_force_sensor_3" pos="0.014598 0.01472 -0.0073103" quat="0.6156583750166776 -0.34779809037949705 -0.6156608522513736 -0.3477973096579549">
                                      <inertial pos="-1.23775059738263E-05 -0.000195169652742258 -0.000791740559016839" quat="1.0 0.0 0.0 0.0" mass="0.001" diaginertia="5.41310691342173e-09 2.55911790350329e-09 7.82908815507693e-09" />
                                      <geom name="right_thumb_force_sensor_3_collision" pos="0 0 0" quat="1.0 0.0 0.0 0.0" type="mesh" mesh="right_thumb_force_sensor_3"  />
                                      <geom name="right_thumb_force_sensor_3_visual" pos="0 0 0" quat="1.0 0.0 0.0 0.0" material="04" type="mesh" mesh="right_thumb_force_sensor_3" />
                                    </body>
                                    <body name="right_thumb_force_sensor_4" pos="0.028987 0.017301 -0.0073512" quat="0.6091480812528507 -0.35908259358280387 0.6091465273096086 0.3590805123624249">
                                      <inertial pos="-7.92360954363081E-07 0.000270176676441192 -0.00100449430451509" quat="1.0 0.0 0.0 0.0" mass="0.001" diaginertia="8.13571079919818e-11 1.7077491736553e-10 2.11640709143909e-10" />
                                      <geom name="right_thumb_force_sensor_4_collision" pos="0 0 0" quat="1.0 0.0 0.0 0.0" type="mesh" mesh="right_thumb_force_sensor_4"  />
                                      <geom name="right_thumb_force_sensor_4_visual" pos="0 0 0" quat="1.0 0.0 0.0 0.0" material="04" type="mesh" mesh="right_thumb_force_sensor_4" />
                                    </body>
                                  </body>
                                </body>
                                <body name="right_thumb_force_sensor_1" pos="0.0087121 0.026305 -0.0067115" quat="0.5793266690814035 -0.4054366611707184 -0.5793281540705502 -0.4054387921388317">
                                  <inertial pos="1.67085981274823E-05 1.15915239991271E-05 -0.00107125254163185" quat="1.0 0.0 0.0 0.0" mass="0.001" diaginertia="9.01126285102489e-09 4.94554439784859e-09 1.35651458253969e-08" />
                                  <geom name="right_thumb_force_sensor_1_collision" pos="0 0 0" quat="1.0 0.0 0.0 0.0" type="mesh" mesh="right_thumb_force_sensor_1"  />
                                  <geom name="right_thumb_force_sensor_1_visual" pos="0 0 0" quat="1.0 0.0 0.0 0.0" material="04" type="mesh" mesh="right_thumb_force_sensor_1" />
                                </body>
                              </body>
                            </body>
                            <body name="right_index_1" pos="-0.038679 0.00056467 0.1564" quat="0.4911974827744529 0.5086484014655795 -0.508650269838915 -0.49119928704686716">
                              <joint name="right_index_1_joint" type="hinge" ref="0.0"  range="0 1.4381" axis="0 0 1" />
                              <inertial pos="-0.00219417482969622 0.0127409366565626 -0.00664941200246505" quat="1.0 0.0 0.0 0.0" mass="0.02841" diaginertia="1.13161497176563e-06 5.50297969803493e-07 1.17483803325344e-06" />
                              <geom name="right_index_1_collision" pos="0 0 0" quat="1.0 0.0 0.0 0.0" type="mesh" mesh="right_index_1"  />
                              <geom name="right_index_1_visual" pos="0 0 0" quat="1.0 0.0 0.0 0.0" material="1" type="mesh" mesh="right_index_1" />
                              <body name="right_index_2" pos="-0.0034259 0.032596 -0.00055" quat="1.0 0.0 0.0 0.0">
                                <joint name="right_index_2_joint" type="hinge" ref="0.0"  range="0 3.14" axis="0 0 1" />
                                <inertial pos="0.00053282674431529 0.0253434850963997 -0.00609291472256712" quat="1.0 0.0 0.0 0.0" mass="0.01218" diaginertia="2.11107718074946e-06 3.7048516715658e-07 2.14315437386293e-06" />
                                <geom name="right_index_2_collision" pos="0 0 0" quat="1.0 0.0 0.0 0.0" type="mesh" mesh="right_index_2"  />
                                <geom name="right_index_2_visual" pos="0 0 0" quat="1.0 0.0 0.0 0.0" material="1" type="mesh" mesh="right_index_2" />
                                <body name="right_index_force_sensor_2" pos="-0.0081655 0.037446 -0.0060795" quat="0.6939850814877147 0.10975830208053111 -0.6985364580606956 0.13558996480900304">
                                  <inertial pos="3.91105790090857E-06 0.000206428506730846 -0.000722888656592813" quat="1.0 0.0 0.0 0.0" mass="0.001" diaginertia="4.79878645065383e-09 2.43958893457374e-09 7.12570334555721e-09" />
                                  <geom name="right_index_force_sensor_2_collision" pos="0 0 0" quat="1.0 0.0 0.0 0.0" type="mesh" mesh="right_index_force_sensor_2"  />
                                  <geom name="right_index_force_sensor_2_visual" pos="0 0 0" quat="1.0 0.0 0.0 0.0" material="04" type="mesh" mesh="right_index_force_sensor_2" />
                                </body>
                                <body name="right_index_force_sensor_3" pos="-0.0086237 0.052572 -0.0060954" quat="0.6697696257071986 -0.25702741334368784 -0.6587389410860489 -0.22673456897156855">
                                  <inertial pos="-2.48722057788475E-05 -0.000345285689256153 -0.00133800038179009" quat="1.0 0.0 0.0 0.0" mass="0.001" diaginertia="1.31974821284448e-10 2.53430134807533e-10 2.8053351791299e-10" />
                                  <geom name="right_index_force_sensor_3_collision" pos="0 0 0" quat="1.0 0.0 0.0 0.0" type="mesh" mesh="right_index_force_sensor_3"  />
                                  <geom name="right_index_force_sensor_3_visual" pos="0 0 0" quat="1.0 0.0 0.0 0.0" material="04" type="mesh" mesh="right_index_force_sensor_3" />
                                </body>
                              </body>
                              <body name="right_index_force_sensor_1" pos="-0.012046 0.019649 -0.006651" quat="0.7043580265419089 -0.08738526375830419 -0.7016864550666019 -0.06228727719161248">
                                <inertial pos="4.50639917342482E-06 0.000116571661332499 -0.000567443126962358" quat="1.0 0.0 0.0 0.0" mass="0.001" diaginertia="3.38028798502951e-09 1.96412698995832e-09 5.28079732652296e-09" />
                                <geom name="right_index_force_sensor_1_collision" pos="0 0 0" quat="1.0 0.0 0.0 0.0" type="mesh" mesh="right_index_force_sensor_1"  />
                                <geom name="right_index_force_sensor_1_visual" pos="0 0 0" quat="1.0 0.0 0.0 0.0" material="04" type="mesh" mesh="right_index_force_sensor_1" />
                              </body>
                            </body>
                            <body name="right_middle_1" pos="-0.0171 0.00056467 0.157" quat="0.4999981633974483 0.49999999999662686 -0.5000018366025516 -0.49999999999662686">
                              <joint name="right_middle_1_joint" type="hinge" ref="0.0"  range="0 1.4381" axis="0 0 1" />
                              <inertial pos="-0.00219417478814514 0.0127409366268324 -0.00664941207814898" quat="1.0 0.0 0.0 0.0" mass="0.02841" diaginertia="1.1316149557554e-06 5.50297969652712e-07 1.17483802522199e-06" />
                              <geom name="right_middle_1_collision" pos="0 0 0" quat="1.0 0.0 0.0 0.0" type="mesh" mesh="right_middle_1"  />
                              <geom name="right_middle_1_visual" pos="0 0 0" quat="1.0 0.0 0.0 0.0" material="1" type="mesh" mesh="right_middle_1" />
                              <body name="right_middle_2" pos="-0.0034259 0.032596 -0.00055" quat="1.0 0.0 0.0 0.0">
                                <joint name="right_middle_2_joint" type="hinge" ref="0.0"  range="0 3.14" axis="0 0 1" />
                                <inertial pos="-9.21583803522863E-05 0.0270332758922563 -0.00610054154137712" quat="1.0 0.0 0.0 0.0" mass="0.01561" diaginertia="2.58635805719435e-06 4.10296161873934e-07 2.62934430889061e-06" />
                                <geom name="right_middle_2_collision" pos="0 0 0" quat="1.0 0.0 0.0 0.0" type="mesh" mesh="right_middle_2"  />
                                <geom name="right_middle_2_visual" pos="0 0 0" quat="1.0 0.0 0.0 0.0" material="1" type="mesh" mesh="right_middle_2" />
                                <body name="right_middle_force_sensor_2" pos="-0.0090859 0.040963 -0.0061003" quat="-0.6950084938544999 -0.13024801540069525 0.6950062906892984 -0.13024939100273075">
                                  <inertial pos="-3.55652627983399E-07 2.88666331397097E-05 -0.000722235489778011" quat="1.0 0.0 0.0 0.0" mass="0.001" diaginertia="5.0422606271269e-09 2.56807850635636e-09 7.49563436241948e-09" />
                                  <geom name="right_middle_force_sensor_2_collision" pos="0 0 0" quat="1.0 0.0 0.0 0.0" type="mesh" mesh="right_middle_force_sensor_2"  />
                                  <geom name="right_middle_force_sensor_2_visual" pos="0 0 0" quat="1.0 0.0 0.0 0.0" material="04" type="mesh" mesh="right_middle_force_sensor_2" />
                                </body>
                                <body name="right_middle_force_sensor_3" pos="-0.0098294 0.056051 -0.0061006" quat="-0.6671014538177903 0.23447278501867314 0.66709900205324 0.23447192765733987">
                                  <inertial pos="6.04731043574169E-08 -0.00036544534557964 -0.00127683945630336" quat="1.0 0.0 0.0 0.0" mass="0.001" diaginertia="1.27227764572837e-10 2.43691164484046e-10 2.7587517056304e-10" />
                                  <geom name="right_middle_force_sensor_3_collision" pos="0 0 0" quat="1.0 0.0 0.0 0.0" type="mesh" mesh="right_middle_force_sensor_3"  />
                                  <geom name="right_middle_force_sensor_3_visual" pos="0 0 0" quat="1.0 0.0 0.0 0.0" material="04" type="mesh" mesh="right_middle_force_sensor_3" />
                                </body>
                              </body>
                              <body name="right_middle_force_sensor_1" pos="-0.012046 0.019649 -0.006651" quat="-0.7030759738899788 0.07540564659811805 0.7030733909146099 0.07540537373165047">
                                <inertial pos="3.42843697213185E-07 0.000116657509605197 -0.000567442695803486" quat="1.0 0.0 0.0 0.0" mass="0.001" diaginertia="3.38208410519618e-09 1.96233204624223e-09 5.2807983995112e-09" />
                                <geom name="right_middle_force_sensor_1_collision" pos="0 0 0" quat="1.0 0.0 0.0 0.0" type="mesh" mesh="right_middle_force_sensor_1"  />
                                <geom name="right_middle_force_sensor_1_visual" pos="0 0 0" quat="1.0 0.0 0.0 0.0" material="04" type="mesh" mesh="right_middle_force_sensor_1" />
                              </body>
                            </body>
                            <body name="right_ring_1" pos="0.0045302 0.00056467 0.15683" quat="0.5129250651682272 0.48672994660244423 -0.4867317344646516 -0.5129269492506545">
                              <joint name="right_ring_1_joint" type="hinge" ref="0.0"  range="0 1.4381" axis="0 0 1" />
                              <inertial pos="-0.00219417465246989 0.0127409362160862 -0.0066494113506478" quat="1.0 0.0 0.0 0.0" mass="0.02841" diaginertia="1.13161521046633e-06 5.50298017624686e-07 1.17483820891763e-06" />
                              <geom name="right_ring_1_collision" pos="0 0 0" quat="1.0 0.0 0.0 0.0" type="mesh" mesh="right_ring_1"  />
                              <geom name="right_ring_1_visual" pos="0 0 0" quat="1.0 0.0 0.0 0.0" material="1" type="mesh" mesh="right_ring_1" />
                              <body name="right_ring_2" pos="-0.0034259 0.032596 -0.00055" quat="1.0 0.0 0.0 0.0">
                                <joint name="right_ring_2_joint" type="hinge" ref="0.0"  range="0 3.14" axis="0 0 1" />
                                <inertial pos="0.000532825578113461 0.02534346612146 -0.00609293344206238" quat="1.0 0.0 0.0 0.0" mass="0.01281" diaginertia="2.1110771068108e-06 3.70485089846105e-07 2.14315369799671e-06" />
                                <geom name="right_ring_2_collision" pos="0 0 0" quat="1.0 0.0 0.0 0.0" type="mesh" mesh="right_ring_2"  />
                                <geom name="right_ring_2_visual" pos="0 0 0" quat="1.0 0.0 0.0 0.0" material="1" type="mesh" mesh="right_ring_2" />
                                <body name="right_ring_force_sensor_2" pos="-0.00816549212353353 0.0374457610846523 -0.00607949056508933" quat="0.6995292421531365 0.14203031983300052 -0.6926957400245326 0.10324165522045514">
                                  <inertial pos="-1.52436836100122E-05 0.000205901966578506 -0.000722888420897932" quat="1.0 0.0 0.0 0.0" mass="0.001" diaginertia="4.79446001367797e-09 2.44391505492957e-09 7.12570290551646e-09" />
                                  <geom name="right_ring_force_sensor_2_collision" pos="0 0 0" quat="1.0 0.0 0.0 0.0" type="mesh" mesh="right_ring_force_sensor_2"  />
                                  <geom name="right_ring_force_sensor_2_visual" pos="0 0 0" quat="1.0 0.0 0.0 0.0" material="04" type="mesh" mesh="right_ring_force_sensor_2" />
                                </body>
                                <body name="right_ring_force_sensor_3" pos="-0.00862372785817732 0.0525719273258207 -0.00609538761271226" quat="0.6557754362662784 -0.21910925425980005 -0.6723028593555983 -0.2644968377689476">
                                  <inertial pos="1.45480090249107E-05 -0.000345868489067203 -0.00133799622683203" quat="1.0 0.0 0.0 0.0" mass="0.001" diaginertia="1.32268380918037e-10 2.53139740379503e-10 2.80536239837899e-10" />
                                  <geom name="right_ring_force_sensor_3_collision" pos="0 0 0" quat="1.0 0.0 0.0 0.0" type="mesh" mesh="right_ring_force_sensor_3"  />
                                  <geom name="right_ring_force_sensor_3_visual" pos="0 0 0" quat="1.0 0.0 0.0 0.0" material="04" type="mesh" mesh="right_ring_force_sensor_3" />
                                </body>
                              </body>
                              <body name="right_ring_force_sensor_1" pos="-0.0120461582060112 0.019648547178991 -0.00665098451502209" quat="0.7008785733464056 -0.05599036488010062 -0.7048865717550545 -0.09364414249651182">
                                <inertial pos="-5.90327958142033E-06 0.000116509445804644 -0.000567443259521572" quat="1.0 0.0 0.0 0.0" mass="0.001" diaginertia="3.37799540185096e-09 1.96641957767428e-09 5.28079735826682e-09" />
                                <geom name="right_ring_force_sensor_1_collision" pos="0 0 0" quat="1.0 0.0 0.0 0.0" type="mesh" mesh="right_ring_force_sensor_1"  />
                                <geom name="right_ring_force_sensor_1_visual" pos="0 0 0" quat="1.0 0.0 0.0 0.0" material="04" type="mesh" mesh="right_ring_force_sensor_1" />
                              </body>
                            </body>
                            <body name="right_little_1" pos="0.025916 0.00056467 0.15365" quat="0.5254762378507275 0.47315207581885754 -0.4731538138066691 -0.525478168036271">
                              <joint name="right_little_1_joint" type="hinge" ref="0.0"  range="0 1.4381" axis="0 0 1" />
                              <inertial pos="-0.00219418424084009 0.0127409391731467 -0.00664940009923338" quat="1.0 0.0 0.0 0.0" mass="0.02841" diaginertia="1.13161476879442e-06 5.50297118553785e-07 1.17483808711618e-06" />
                              <geom name="right_little_1_collision" pos="0 0 0" quat="1.0 0.0 0.0 0.0" type="mesh" mesh="right_little_1"  />
                              <geom name="right_little_1_visual" pos="0 0 0" quat="1.0 0.0 0.0 0.0" material="1" type="mesh" mesh="right_little_1" />
                              <body name="right_little_2" pos="-0.0034259 0.032596 -0.00055" quat="1.0 0.0 0.0 0.0">
                                <joint name="right_little_2_joint" type="hinge" ref="0.0"  range="0 3.14" axis="0 0 1" />
                                <inertial pos="0.00142962322858008 0.0206390061213492 -0.00609937271859847" quat="1.0 0.0 0.0 0.0" mass="0.00957" diaginertia="1.1469386346846e-06 2.66181840844389e-07 1.15056368955352e-06" />
                                <geom name="right_little_2_collision" pos="0 0 0" quat="1.0 0.0 0.0 0.0" type="mesh" mesh="right_little_2"  />
                                <geom name="right_little_2_visual" pos="0 0 0" quat="1.0 0.0 0.0 0.0" material="1" type="mesh" mesh="right_little_2" />
                                <body name="right_little_force_sensor_2" pos="-0.00645123763174135 0.0276833479200767 -0.00611719352979621" quat="0.7024034415904223 0.15879741747661485 -0.6890452671651963 0.08142115966952934">
                                  <inertial pos="1.83850807690782E-05 -0.000118792499944516 -0.00077353663965421" quat="1.0 0.0 0.0 0.0" mass="0.001" diaginertia="5.36105565367509e-09 2.78924633862048e-09 8.01055296833179e-09" />
                                  <geom name="right_little_force_sensor_2_collision" pos="0 0 0" quat="1.0 0.0 0.0 0.0" type="mesh" mesh="right_little_force_sensor_2"  />
                                  <geom name="right_little_force_sensor_2_visual" pos="0 0 0" quat="1.0 0.0 0.0 0.0" material="04" type="mesh" mesh="right_little_force_sensor_2" />
                                </body>
                                <body name="right_little_force_sensor_3" pos="-0.00639723214432697 0.042706921918282 -0.00611537168168175" quat="0.6452963993866153 -0.19817031150619066 -0.6787698635307402 -0.2891237744265759">
                                  <inertial pos="6.36863053951123E-05 -0.000437236774208316 -0.00112814037373121" quat="1.0 0.0 0.0 0.0" mass="0.001" diaginertia="1.11592356002466e-10 2.17209112811676e-10 2.52055535156648e-10" />
                                  <geom name="right_little_force_sensor_3_collision" pos="0 0 0" quat="1.0 0.0 0.0 0.0" type="mesh" mesh="right_little_force_sensor_3"  />
                                  <geom name="right_little_force_sensor_3_visual" pos="0 0 0" quat="1.0 0.0 0.0 0.0" material="04" type="mesh" mesh="right_little_force_sensor_3" />
                                </body>
                              </body>
                              <body name="right_little_force_sensor_1" pos="-0.0120461582060113 0.0196485471789908 -0.00665098451502223" quat="0.6981206656968678 -0.03710128590505857 -0.706132774047623 -0.11237231032136868">
                                <inertial pos="-1.2130080955873E-05 0.000116026903212899 -0.00056744299424992" quat="1.0 0.0 0.0 0.0" mass="0.001" diaginertia="3.3658199564233e-09 1.97859528185445e-09 5.28079755559196e-09" />
                                <geom name="right_little_force_sensor_1_collision" pos="0 0 0" quat="1.0 0.0 0.0 0.0" type="mesh" mesh="right_little_force_sensor_1"  />
                                <geom name="right_little_force_sensor_1_visual" pos="0 0 0" quat="1.0 0.0 0.0 0.0" material="04" type="mesh" mesh="right_little_force_sensor_1" />
                              </body>
                            </body>
                          </body>
                        </body>
                      </body>
                    </body>
                  </body>
                </body>
              </body>
            </body>
          </body>
        </body>
      </body>
      <camera name="front_camera" mode="track" fovy="90.0" quat="4.329780281177467e-17 4.329780281177466e-17 0.7071067811865475 0.7071067811865476" pos="0.0 2.0 0.5" />
      <camera name="side_camera" mode="track" fovy="90.0" quat="-0.5 -0.4999999999999999 0.5 0.5000000000000001" pos="-2.0 0.0 0.5" />
    </body>
  </worldbody>

 <actuator>
    <motor name="left_hip_pitch_joint_ctrl" joint="left_hip_pitch_joint"/>
    <motor name="left_hip_roll_joint_ctrl" joint="left_hip_roll_joint"/>
    <motor name="left_hip_yaw_joint_ctrl" joint="left_hip_yaw_joint"/>
    <motor name="left_knee_joint_ctrl" joint="left_knee_joint"/>
    <motor name="left_ankle_pitch_joint_ctrl" joint="left_ankle_pitch_joint"/>
    <motor name="left_ankle_roll_joint_ctrl" joint="left_ankle_roll_joint"/>

    <motor name="right_hip_pitch_joint_ctrl" joint="right_hip_pitch_joint"/>
    <motor name="right_hip_roll_joint_ctrl" joint="right_hip_roll_joint"/>
    <motor name="right_hip_yaw_joint_ctrl" joint="right_hip_yaw_joint"/>
    <motor name="right_knee_joint_ctrl" joint="right_knee_joint"/>
    <motor name="right_ankle_pitch_joint_ctrl" joint="right_ankle_pitch_joint"/>
    <motor name="right_ankle_roll_joint_ctrl" joint="right_ankle_roll_joint"/>

    <motor name="waist_yaw_joint_ctrl" joint="waist_yaw_joint"/>
    <motor name="waist_roll_joint_ctrl" joint="waist_roll_joint"/>
    <motor name="waist_pitch_joint_ctrl" joint="waist_pitch_joint"/>

    <motor name="left_shoulder_pitch_joint_ctrl" joint="left_shoulder_pitch_joint"/>
    <motor name="left_shoulder_roll_joint_ctrl" joint="left_shoulder_roll_joint"/>
    <motor name="left_shoulder_yaw_joint_ctrl" joint="left_shoulder_yaw_joint"/>
    <motor name="left_elbow_joint_ctrl" joint="left_elbow_joint"/>
    <motor name="left_wrist_roll_joint_ctrl" joint="left_wrist_roll_joint"/>
    <motor name="left_wrist_pitch_joint_ctrl" joint="left_wrist_pitch_joint"/>
    <motor name="left_wrist_yaw_joint_ctrl" joint="left_wrist_yaw_joint"/>

    <motor name="left_thumb_1_joint_ctrl" joint="left_thumb_1_joint"/>
    <motor name="left_thumb_2_joint_ctrl" joint="left_thumb_2_joint"/>
    <motor name="left_thumb_3_joint_ctrl" joint="left_thumb_3_joint"/>
    <motor name="left_thumb_4_joint_ctrl" joint="left_thumb_4_joint"/>
    <motor name="left_index_1_joint_ctrl" joint="left_index_1_joint"/>
    <motor name="left_index_2_joint_ctrl" joint="left_index_2_joint"/>
    <motor name="left_middle_1_joint_ctrl" joint="left_middle_1_joint"/>
    <motor name="left_middle_2_joint_ctrl" joint="left_middle_2_joint"/>
    <motor name="left_ring_1_joint_ctrl" joint="left_ring_1_joint"/>
    <motor name="left_ring_2_joint_ctrl" joint="left_ring_2_joint"/>
    <motor name="left_little_1_joint_ctrl" joint="left_little_1_joint"/>
    <motor name="left_little_2_joint_ctrl" joint="left_little_2_joint"/>

    <motor name="right_shoulder_pitch_joint_ctrl" joint="right_shoulder_pitch_joint"/>
    <motor name="right_shoulder_roll_joint_ctrl" joint="right_shoulder_roll_joint"/>
    <motor name="right_shoulder_yaw_joint_ctrl" joint="right_shoulder_yaw_joint"/>
    <motor name="right_elbow_joint_ctrl" joint="right_elbow_joint"/>
    <motor name="right_wrist_roll_joint_ctrl" joint="right_wrist_roll_joint"/>
    <motor name="right_wrist_pitch_joint_ctrl" joint="right_wrist_pitch_joint"/>
    <motor name="right_wrist_yaw_joint_ctrl" joint="right_wrist_yaw_joint"/>

    <motor name="right_thumb_1_joint_ctrl" joint="right_thumb_1_joint"/>
    <motor name="right_thumb_2_joint_ctrl" joint="right_thumb_2_joint"/>
    <motor name="right_thumb_3_joint_ctrl" joint="right_thumb_3_joint"/>
    <motor name="right_thumb_4_joint_ctrl" joint="right_thumb_4_joint"/>
    <motor name="right_index_1_joint_ctrl" joint="right_index_1_joint"/>
    <motor name="right_index_2_joint_ctrl" joint="right_index_2_joint"/>
    <motor name="right_middle_1_joint_ctrl" joint="right_middle_1_joint"/>
    <motor name="right_middle_2_joint_ctrl" joint="right_middle_2_joint"/>
    <motor name="right_ring_1_joint_ctrl" joint="right_ring_1_joint"/>
    <motor name="right_ring_2_joint_ctrl" joint="right_ring_2_joint"/>
    <motor name="right_little_1_joint_ctrl" joint="right_little_1_joint"/>
    <motor name="right_little_2_joint_ctrl" joint="right_little_2_joint"/>
  </actuator>


  <contact>
    <exclude body1="left_hip_pitch_link" body2="left_hip_roll_link" />
    <exclude body1="left_hip_roll_link" body2="left_hip_yaw_link" />
    <exclude body1="left_hip_yaw_link" body2="left_knee_link" />
    <exclude body1="left_knee_link" body2="left_ankle_pitch_link" />
    <exclude body1="left_ankle_pitch_link" body2="left_ankle_roll_link" />
    <exclude body1="right_hip_pitch_link" body2="right_hip_roll_link" />
    <exclude body1="right_hip_roll_link" body2="right_hip_yaw_link" />
    <exclude body1="right_hip_yaw_link" body2="right_knee_link" />
    <exclude body1="right_knee_link" body2="right_ankle_pitch_link" />
    <exclude body1="right_ankle_pitch_link" body2="right_ankle_roll_link" />
    <exclude body1="torso_link" body2="logo_link" />
    <exclude body1="torso_link" body2="head_link" />
    <exclude body1="torso_link" body2="left_shoulder_pitch_link" />
    <exclude body1="left_shoulder_pitch_link" body2="left_shoulder_roll_link" />
    <exclude body1="left_shoulder_roll_link" body2="left_shoulder_yaw_link" />
    <exclude body1="left_shoulder_yaw_link" body2="left_elbow_link" />
    <exclude body1="left_elbow_link" body2="left_wrist_roll_link" />
    <exclude body1="left_wrist_roll_link" body2="left_wrist_pitch_link" />
    <exclude body1="left_wrist_pitch_link" body2="left_wrist_yaw_link" />
    <exclude body1="torso_link" body2="right_shoulder_pitch_link" />
    <exclude body1="right_shoulder_pitch_link" body2="right_shoulder_roll_link" />
    <exclude body1="right_shoulder_roll_link" body2="right_shoulder_yaw_link" />
    <exclude body1="right_shoulder_yaw_link" body2="right_elbow_link" />
    <exclude body1="right_elbow_link" body2="right_wrist_roll_link" />
    <exclude body1="right_wrist_roll_link" body2="right_wrist_pitch_link" />
    <exclude body1="right_wrist_pitch_link" body2="right_wrist_yaw_link" />
    <exclude body1="left_wrist_yaw_link" body2="left_base_link" />
    <exclude body1="left_base_link" body2="left_palm_force_sensor" />
    <exclude body1="left_base_link" body2="left_thumb_1" />
    <exclude body1="left_thumb_1" body2="left_thumb_2" />
    <exclude body1="left_thumb_2" body2="left_thumb_force_sensor_1" />
    <exclude body1="left_thumb_2" body2="left_thumb_3" />
    <exclude body1="left_thumb_3" body2="left_thumb_force_sensor_2" />
    <exclude body1="left_thumb_3" body2="left_thumb_4" />
    <exclude body1="left_thumb_4" body2="left_thumb_force_sensor_3" />
    <exclude body1="left_thumb_4" body2="left_thumb_force_sensor_4" />
    <exclude body1="left_base_link" body2="left_index_1" />
    <exclude body1="left_index_1" body2="left_index_force_sensor_1" />
    <exclude body1="left_index_1" body2="left_index_2" />
    <exclude body1="left_index_2" body2="left_index_force_sensor_2" />
    <exclude body1="left_index_2" body2="left_index_force_sensor_3" />
    <exclude body1="left_base_link" body2="left_middle_1" />
    <exclude body1="left_middle_1" body2="left_middle_force_sensor_1" />
    <exclude body1="left_middle_1" body2="left_middle_2" />
    <exclude body1="left_middle_2" body2="left_middle_force_sensor_2" />
    <exclude body1="left_middle_2" body2="left_middle_force_sensor_3" />
    <exclude body1="left_base_link" body2="left_ring_1" />
    <exclude body1="left_ring_1" body2="left_ring_force_sensor_1" />
    <exclude body1="left_ring_1" body2="left_ring_2" />
    <exclude body1="left_ring_2" body2="left_ring_force_sensor_2" />
    <exclude body1="left_ring_2" body2="left_ring_force_sensor_3" />
    <exclude body1="left_base_link" body2="left_little_1" />
    <exclude body1="left_little_1" body2="left_little_force_sensor_1" />
    <exclude body1="left_little_1" body2="left_little_2" />
    <exclude body1="left_little_2" body2="left_little_force_sensor_2" />
    <exclude body1="left_little_2" body2="left_little_force_sensor_3" />
    <exclude body1="right_wrist_yaw_link" body2="right_base_link" />
    <exclude body1="right_base_link" body2="right_palm_force_sensor" />
    <exclude body1="right_base_link" body2="right_thumb_1" />
    <exclude body1="right_thumb_1" body2="right_thumb_2" />
    <exclude body1="right_thumb_2" body2="right_thumb_3" />
    <exclude body1="right_thumb_3" body2="right_thumb_force_sensor_2" />
    <exclude body1="right_thumb_3" body2="right_thumb_4" />
    <exclude body1="right_thumb_4" body2="right_thumb_force_sensor_3" />
    <exclude body1="right_thumb_4" body2="right_thumb_force_sensor_4" />
    <exclude body1="right_thumb_2" body2="right_thumb_force_sensor_1" />
    <exclude body1="right_base_link" body2="right_index_1" />
    <exclude body1="right_index_1" body2="right_index_2" />
    <exclude body1="right_index_2" body2="right_index_force_sensor_2" />
    <exclude body1="right_index_2" body2="right_index_force_sensor_3" />
    <exclude body1="right_index_1" body2="right_index_force_sensor_1" />
    <exclude body1="right_base_link" body2="right_middle_1" />
    <exclude body1="right_middle_1" body2="right_middle_2" />
    <exclude body1="right_middle_2" body2="right_middle_force_sensor_2" />
    <exclude body1="right_middle_2" body2="right_middle_force_sensor_3" />
    <exclude body1="right_middle_1" body2="right_middle_force_sensor_1" />
    <exclude body1="right_base_link" body2="right_ring_1" />
    <exclude body1="right_ring_1" body2="right_ring_2" />
    <exclude body1="right_ring_2" body2="right_ring_force_sensor_2" />
    <exclude body1="right_ring_2" body2="right_ring_force_sensor_3" />
    <exclude body1="right_ring_1" body2="right_ring_force_sensor_1" />
    <exclude body1="right_base_link" body2="right_little_1" />
    <exclude body1="right_little_1" body2="right_little_2" />
    <exclude body1="right_little_2" body2="right_little_force_sensor_2" />
    <exclude body1="right_little_2" body2="right_little_force_sensor_3" />
    <exclude body1="right_little_1" body2="right_little_force_sensor_1" />
  </contact>

  <sensor>
    <jointpos name="left_hip_pitch_pos" joint="left_hip_pitch_joint"/>
    <jointpos name="left_hip_roll_pos" joint="left_hip_roll_joint"/>
    <jointpos name="left_hip_yaw_pos" joint="left_hip_yaw_joint"/>
    <jointpos name="left_knee_pos" joint="left_knee_joint"/>
    <jointpos name="left_ankle_pitch_pos" joint="left_ankle_pitch_joint"/>
    <jointpos name="left_ankle_roll_pos" joint="left_ankle_roll_joint"/>
    <jointpos name="right_hip_pitch_pos" joint="right_hip_pitch_joint"/>
    <jointpos name="right_hip_roll_pos" joint="right_hip_roll_joint"/>
    <jointpos name="right_hip_yaw_pos" joint="right_hip_yaw_joint"/>
    <jointpos name="right_knee_pos" joint="right_knee_joint"/>
    <jointpos name="right_ankle_pitch_pos" joint="right_ankle_pitch_joint"/>
    <jointpos name="right_ankle_roll_pos" joint="right_ankle_roll_joint"/>
    <jointpos name="waist_yaw_pos" joint="waist_yaw_joint"/>
    <jointpos name="waist_roll_pos" joint="waist_roll_joint"/>
    <jointpos name="waist_pitch_pos" joint="waist_pitch_joint"/>
    <jointpos name="left_shoulder_pitch_pos" joint="left_shoulder_pitch_joint"/>
    <jointpos name="left_shoulder_roll_pos" joint="left_shoulder_roll_joint"/>
    <jointpos name="left_shoulder_yaw_pos" joint="left_shoulder_yaw_joint"/>
    <jointpos name="left_elbow_pos" joint="left_elbow_joint"/>
    <jointpos name="left_wrist_roll_pos" joint="left_wrist_roll_joint"/>
    <jointpos name="left_wrist_pitch_pos" joint="left_wrist_pitch_joint"/>
    <jointpos name="left_wrist_yaw_pos" joint="left_wrist_yaw_joint"/>
    <jointpos name="right_shoulder_pitch_pos" joint="right_shoulder_pitch_joint"/>
    <jointpos name="right_shoulder_roll_pos" joint="right_shoulder_roll_joint"/>
    <jointpos name="right_shoulder_yaw_pos" joint="right_shoulder_yaw_joint"/>
    <jointpos name="right_elbow_pos" joint="right_elbow_joint"/>
    <jointpos name="right_wrist_roll_pos" joint="right_wrist_roll_joint"/>
    <jointpos name="right_wrist_pitch_pos" joint="right_wrist_pitch_joint"/>
    <jointpos name="right_wrist_yaw_pos" joint="right_wrist_yaw_joint"/>

    <jointvel name="left_hip_pitch_vel" joint="left_hip_pitch_joint"/>
    <jointvel name="left_hip_roll_vel" joint="left_hip_roll_joint"/>
    <jointvel name="left_hip_yaw_vel" joint="left_hip_yaw_joint"/>
    <jointvel name="left_knee_vel" joint="left_knee_joint"/>
    <jointvel name="left_ankle_pitch_vel" joint="left_ankle_pitch_joint"/>
    <jointvel name="left_ankle_roll_vel" joint="left_ankle_roll_joint"/>
    <jointvel name="right_hip_pitch_vel" joint="right_hip_pitch_joint"/>
    <jointvel name="right_hip_roll_vel" joint="right_hip_roll_joint"/>
    <jointvel name="right_hip_yaw_vel" joint="right_hip_yaw_joint"/>
    <jointvel name="right_knee_vel" joint="right_knee_joint"/>
    <jointvel name="right_ankle_pitch_vel" joint="right_ankle_pitch_joint"/>
    <jointvel name="right_ankle_roll_vel" joint="right_ankle_roll_joint"/>
    <jointvel name="waist_yaw_vel" joint="waist_yaw_joint"/>
    <jointvel name="waist_roll_vel" joint="waist_roll_joint"/>
    <jointvel name="waist_pitch_vel" joint="waist_pitch_joint"/>
    <jointvel name="left_shoulder_pitch_vel" joint="left_shoulder_pitch_joint"/>
    <jointvel name="left_shoulder_roll_vel" joint="left_shoulder_roll_joint"/>
    <jointvel name="left_shoulder_yaw_vel" joint="left_shoulder_yaw_joint"/>
    <jointvel name="left_elbow_vel" joint="left_elbow_joint"/>
    <jointvel name="left_wrist_roll_vel" joint="left_wrist_roll_joint"/>
    <jointvel name="left_wrist_pitch_vel" joint="left_wrist_pitch_joint"/>
    <jointvel name="left_wrist_yaw_vel" joint="left_wrist_yaw_joint"/>
    <jointvel name="right_shoulder_pitch_vel" joint="right_shoulder_pitch_joint"/>
    <jointvel name="right_shoulder_roll_vel" joint="right_shoulder_roll_joint"/>
    <jointvel name="right_shoulder_yaw_vel" joint="right_shoulder_yaw_joint"/>
    <jointvel name="right_elbow_vel" joint="right_elbow_joint"/>
    <jointvel name="right_wrist_roll_vel" joint="right_wrist_roll_joint"/>
    <jointvel name="right_wrist_pitch_vel" joint="right_wrist_pitch_joint"/>
    <jointvel name="right_wrist_yaw_vel" joint="right_wrist_yaw_joint"/>

    <jointactuatorfrc name="left_hip_pitch_torque" joint="left_hip_pitch_joint"/>
    <jointactuatorfrc name="left_hip_roll_torque" joint="left_hip_roll_joint"/>
    <jointactuatorfrc name="left_hip_yaw_torque" joint="left_hip_yaw_joint"/>
    <jointactuatorfrc name="left_knee_torque" joint="left_knee_joint"/>
    <jointactuatorfrc name="left_ankle_pitch_torque" joint="left_ankle_pitch_joint"/>
    <jointactuatorfrc name="left_ankle_roll_torque" joint="left_ankle_roll_joint"/>
    <jointactuatorfrc name="right_hip_pitch_torque" joint="right_hip_pitch_joint"/>
    <jointactuatorfrc name="right_hip_roll_torque" joint="right_hip_roll_joint"/>
    <jointactuatorfrc name="right_hip_yaw_torque" joint="right_hip_yaw_joint"/>
    <jointactuatorfrc name="right_knee_torque" joint="right_knee_joint"/>
    <jointactuatorfrc name="right_ankle_pitch_torque" joint="right_ankle_pitch_joint"/>
    <jointactuatorfrc name="right_ankle_roll_torque" joint="right_ankle_roll_joint"/>
    <jointactuatorfrc name="waist_yaw_torque" joint="waist_yaw_joint"/>
    <jointactuatorfrc name="waist_roll_torque" joint="waist_roll_joint"/>
    <jointactuatorfrc name="waist_pitch_torque" joint="waist_pitch_joint"/>
    <jointactuatorfrc name="left_shoulder_pitch_torque" joint="left_shoulder_pitch_joint"/>
    <jointactuatorfrc name="left_shoulder_roll_torque" joint="left_shoulder_roll_joint"/>
    <jointactuatorfrc name="left_shoulder_yaw_torque" joint="left_shoulder_yaw_joint"/>
    <jointactuatorfrc name="left_elbow_torque" joint="left_elbow_joint"/>
    <jointactuatorfrc name="left_wrist_roll_torque" joint="left_wrist_roll_joint"/>
    <jointactuatorfrc name="left_wrist_pitch_torque" joint="left_wrist_pitch_joint"/>
    <jointactuatorfrc name="left_wrist_yaw_torque" joint="left_wrist_yaw_joint"/>
    <jointactuatorfrc name="right_shoulder_pitch_torque" joint="right_shoulder_pitch_joint"/>
    <jointactuatorfrc name="right_shoulder_roll_torque" joint="right_shoulder_roll_joint"/>
    <jointactuatorfrc name="right_shoulder_yaw_torque" joint="right_shoulder_yaw_joint"/>
    <jointactuatorfrc name="right_elbow_torque" joint="right_elbow_joint"/>
    <jointactuatorfrc name="right_wrist_roll_torque" joint="right_wrist_roll_joint"/>
    <jointactuatorfrc name="right_wrist_pitch_torque" joint="right_wrist_pitch_joint"/>
    <jointactuatorfrc name="right_wrist_yaw_torque" joint="right_wrist_yaw_joint"/>

    <framequat name="imu_quat" objtype="site" objname="imu"/>
    <gyro name="imu_gyro" site="imu"/>
    <accelerometer name="imu_acc" site="imu"/>

    <framepos name="frame_pos" objtype="site" objname="imu"/>
    <framelinvel name="frame_vel" objtype="site" objname="imu"/>
  </sensor>

  <asset>
    <texture type="skybox" builtin="flat" rgb1="0 0 0" rgb2="0 0 0" width="512" height="3072"/>
    <texture type="2d" name="groundplane" builtin="checker" mark="edge" rgb1="0.2 0.3 0.4" rgb2="0.1 0.2 0.3" markrgb="0.8 0.8 0.8" width="300" height="300"/>
    <material name="groundplane" texture="groundplane" texuniform="true" texrepeat="5 5" reflectance="0.2"/>
  </asset>

  <worldbody>
    <light pos="1 0 3.5" dir="0 0 -1" directional="true"/>
    <geom name="floor" size="0 0 0.05" type="plane" material="groundplane"/>
  </worldbody>
</mujoco>